INFO 2025-10-29 13:43:53,830 autoreload 92 139679628725184 /app/users/api_views.py changed, reloading.
INFO 2025-10-29 13:43:54,645 autoreload 221 140345122286528 Watching for file changes with StatReloader
INFO 2025-10-29 13:45:34,802 autoreload 221 140345122286528 /app/users/api_views.py changed, reloading.
INFO 2025-10-29 13:45:35,613 autoreload 246 139815221439424 Watching for file changes with StatReloader
INFO 2025-10-29 13:46:07,062 autoreload 246 139815221439424 /app/users/models.py changed, reloading.
INFO 2025-10-29 13:46:07,814 autoreload 256 140573866560448 Watching for file changes with StatReloader
INFO 2025-10-29 13:46:20,523 autoreload 256 140573866560448 /app/users/models.py changed, reloading.
INFO 2025-10-29 13:46:21,313 autoreload 258 140328837938112 Watching for file changes with StatReloader
INFO 2025-10-29 13:46:47,207 autoreload 258 140328837938112 /app/users/api_urls.py changed, reloading.
INFO 2025-10-29 13:46:48,015 autoreload 268 140177955797952 Watching for file changes with StatReloader
INFO 2025-10-29 13:46:59,013 autoreload 268 140177955797952 /app/users/api_urls.py changed, reloading.
INFO 2025-10-29 13:46:59,841 autoreload 278 140376028310464 Watching for file changes with StatReloader
INFO 2025-10-29 13:48:08,287 autoreload 278 140376028310464 /app/crm/settings.py changed, reloading.
INFO 2025-10-29 13:48:09,120 autoreload 294 139774884154304 Watching for file changes with StatReloader
INFO 2025-10-29 13:48:59,842 autoreload 11 140261913508800 Watching for file changes with StatReloader
INFO 2025-10-29 13:50:23,326 autoreload 11 139738294053824 Watching for file changes with StatReloader
INFO 2025-10-29 13:53:22,739 autoreload 92 140612304047040 Watching for file changes with StatReloader
INFO 2025-10-29 13:56:00,947 autoreload 11 140594771667904 Watching for file changes with StatReloader
INFO 2025-10-29 14:09:01,139 autoreload 92 140469967797184 Watching for file changes with StatReloader
INFO 2025-10-29 14:11:32,995 autoreload 11 139625881893824 Watching for file changes with StatReloader
INFO 2025-10-29 14:14:54,208 autoreload 11 139625881893824 /app/crm/settings.py changed, reloading.
INFO 2025-10-29 14:14:55,005 autoreload 34 140542617627584 Watching for file changes with StatReloader
INFO 2025-10-29 14:15:55,071 autoreload 34 140542617627584 /app/crm/settings.py changed, reloading.
INFO 2025-10-29 14:15:55,975 autoreload 38 140330792569792 Watching for file changes with StatReloader
INFO 2025-10-29 14:16:22,091 autoreload 38 140330792569792 /app/crm/settings.py changed, reloading.
INFO 2025-10-29 14:16:23,001 autoreload 42 140196447566784 Watching for file changes with StatReloader
INFO 2025-10-29 14:18:05,759 autoreload 42 140196447566784 /app/crm/settings.py changed, reloading.
INFO 2025-10-29 14:18:06,522 autoreload 58 140693372177344 Watching for file changes with StatReloader
ERROR 2025-10-29 14:18:45,288 signal 10 140340514061248 Signal handler <bound method DjangoFixup.on_import_modules of <celery.fixups.django.DjangoFixup object at 0x7fa3909234d0>> raised: ValueError("'e' is not a valid AppSettings.LoginMethod")
Traceback (most recent call last):
  File "/app/.venv/lib/python3.13/site-packages/celery/utils/dispatch/signal.py", line 280, in send
    response = receiver(signal=self, sender=sender, **named)
  File "/app/.venv/lib/python3.13/site-packages/celery/fixups/django.py", line 101, in on_import_modules
    self.worker_fixup.validate_models()
    ~~~~~~~~~~~~~~~~~~~~~~~~~~~~~~~~~^^
  File "/app/.venv/lib/python3.13/site-packages/celery/fixups/django.py", line 141, in validate_models
    run_checks()
    ~~~~~~~~~~^^
  File "/app/.venv/lib/python3.13/site-packages/django/core/checks/registry.py", line 89, in run_checks
    new_errors = check(app_configs=app_configs, databases=databases)
  File "/app/.venv/lib/python3.13/site-packages/allauth/account/checks.py", line 72, in settings_check
    for lm in app_settings.LOGIN_METHODS
              ^^^^^^^^^^^^^^^^^^^^^^^^^^
  File "/app/.venv/lib/python3.13/site-packages/allauth/account/app_settings.py", line 585, in __getattr__
    return getattr(_app_settings, name)
  File "/app/.venv/lib/python3.13/site-packages/allauth/account/app_settings.py", line 169, in LOGIN_METHODS
    return frozenset([self.LoginMethod(m) for m in methods])
                      ~~~~~~~~~~~~~~~~^^^
  File "/usr/local/lib/python3.13/enum.py", line 726, in __call__
    return cls.__new__(cls, value)
           ~~~~~~~~~~~^^^^^^^^^^^^
  File "/usr/local/lib/python3.13/enum.py", line 1203, in __new__
    raise ve_exc
ValueError: 'e' is not a valid AppSettings.LoginMethod
ERROR 2025-10-29 14:18:45,323 signal 10 140506408672192 Signal handler <bound method DjangoFixup.on_import_modules of <celery.fixups.django.DjangoFixup object at 0x7fca30a9f4d0>> raised: ValueError("'e' is not a valid AppSettings.LoginMethod")
Traceback (most recent call last):
  File "/app/.venv/lib/python3.13/site-packages/celery/utils/dispatch/signal.py", line 280, in send
    response = receiver(signal=self, sender=sender, **named)
  File "/app/.venv/lib/python3.13/site-packages/celery/fixups/django.py", line 101, in on_import_modules
    self.worker_fixup.validate_models()
    ~~~~~~~~~~~~~~~~~~~~~~~~~~~~~~~~~^^
  File "/app/.venv/lib/python3.13/site-packages/celery/fixups/django.py", line 141, in validate_models
    run_checks()
    ~~~~~~~~~~^^
  File "/app/.venv/lib/python3.13/site-packages/django/core/checks/registry.py", line 89, in run_checks
    new_errors = check(app_configs=app_configs, databases=databases)
  File "/app/.venv/lib/python3.13/site-packages/allauth/account/checks.py", line 72, in settings_check
    for lm in app_settings.LOGIN_METHODS
              ^^^^^^^^^^^^^^^^^^^^^^^^^^
  File "/app/.venv/lib/python3.13/site-packages/allauth/account/app_settings.py", line 585, in __getattr__
    return getattr(_app_settings, name)
  File "/app/.venv/lib/python3.13/site-packages/allauth/account/app_settings.py", line 169, in LOGIN_METHODS
    return frozenset([self.LoginMethod(m) for m in methods])
                      ~~~~~~~~~~~~~~~~^^^
  File "/usr/local/lib/python3.13/enum.py", line 726, in __call__
    return cls.__new__(cls, value)
           ~~~~~~~~~~~^^^^^^^^^^^^
  File "/usr/local/lib/python3.13/enum.py", line 1203, in __new__
    raise ve_exc
ValueError: 'e' is not a valid AppSettings.LoginMethod
INFO 2025-10-29 14:18:46,311 autoreload 11 140559505062848 Watching for file changes with StatReloader
INFO 2025-10-29 14:19:48,077 autoreload 11 140559505062848 /app/crm/settings.py changed, reloading.
INFO 2025-10-29 14:19:48,871 autoreload 15 140266051759040 Watching for file changes with StatReloader
INFO 2025-10-29 14:21:06,346 autoreload 15 140266051759040 /app/companies/admin.py changed, reloading.
INFO 2025-10-29 14:21:07,135 autoreload 19 140068840836032 Watching for file changes with StatReloader
INFO 2025-10-29 14:21:18,603 autoreload 19 140068840836032 /app/companies/admin.py changed, reloading.
INFO 2025-10-29 14:21:19,446 autoreload 23 140043432512448 Watching for file changes with StatReloader
INFO 2025-10-29 14:21:32,999 autoreload 23 140043432512448 /app/companies/admin.py changed, reloading.
INFO 2025-10-29 14:21:33,927 autoreload 27 139865258490816 Watching for file changes with StatReloader
INFO 2025-10-29 14:21:45,403 autoreload 27 139865258490816 /app/companies/admin.py changed, reloading.
INFO 2025-10-29 14:21:46,229 autoreload 31 140029767166912 Watching for file changes with StatReloader
INFO 2025-10-29 14:21:57,790 autoreload 31 140029767166912 /app/companies/admin.py changed, reloading.
INFO 2025-10-29 14:21:59,150 autoreload 35 140362719914944 Watching for file changes with StatReloader
INFO 2025-10-29 14:22:09,619 autoreload 35 140362719914944 /app/companies/admin.py changed, reloading.
INFO 2025-10-29 14:22:10,458 autoreload 39 140133181479872 Watching for file changes with StatReloader
INFO 2025-10-29 14:22:20,884 autoreload 39 140133181479872 /app/companies/admin.py changed, reloading.
INFO 2025-10-29 14:22:21,796 autoreload 43 140512764148672 Watching for file changes with StatReloader
INFO 2025-10-29 14:22:46,193 autoreload 10 139665919482816 Watching for file changes with StatReloader
INFO 2025-10-29 14:23:09,886 autoreload 10 139832652262336 Watching for file changes with StatReloader
INFO 2025-10-29 14:24:54,481 autoreload 11 140399859854272 Watching for file changes with StatReloader
INFO 2025-10-29 14:25:12,491 autoreload 10 140347759762368 Watching for file changes with StatReloader
INFO 2025-10-29 14:28:12,757 autoreload 11 140096516320192 Watching for file changes with StatReloader
INFO 2025-10-29 14:28:28,615 autoreload 11 140353508920256 Watching for file changes with StatReloader
INFO 2025-10-29 14:30:03,571 autoreload 11 139794723658688 Watching for file changes with StatReloader
INFO 2025-10-29 14:35:30,833 autoreload 92 140172755741632 Watching for file changes with StatReloader
INFO 2025-10-29 14:36:23,449 autoreload 11 140587712334784 Watching for file changes with StatReloader
INFO 2025-10-29 14:36:30,556 autoreload 10 139975688629184 Watching for file changes with StatReloader
INFO 2025-10-29 14:36:55,063 autoreload 12 140376051399616 Watching for file changes with StatReloader
INFO 2025-10-29 14:38:29,326 autoreload 11 139825106938816 Watching for file changes with StatReloader
INFO 2025-10-29 14:38:54,840 autoreload 12 139626651315136 Watching for file changes with StatReloader
INFO 2025-10-29 14:40:20,645 autoreload 11 140156040395712 Watching for file changes with StatReloader
INFO 2025-10-29 15:05:59,362 autoreload 19 139661378911168 Watching for file changes with StatReloader
INFO 2025-10-29 15:06:17,847 autoreload 10 140607360883648 Watching for file changes with StatReloader
INFO 2025-10-29 15:07:06,901 autoreload 10 140607360883648 /app/companies/admin.py changed, reloading.
INFO 2025-10-29 15:07:14,353 autoreload 14 139908820110272 Watching for file changes with StatReloader
INFO 2025-10-29 15:07:37,600 autoreload 14 139908820110272 /app/contacts/admin.py changed, reloading.
INFO 2025-10-29 15:07:44,029 autoreload 18 140049357212608 Watching for file changes with StatReloader
INFO 2025-10-29 15:08:05,349 autoreload 18 140049357212608 /app/crm/settings.py changed, reloading.
INFO 2025-10-29 15:08:11,603 autoreload 22 139676181466048 Watching for file changes with StatReloader
INFO 2025-10-29 15:15:31,541 autoreload 82 140189919349696 Watching for file changes with StatReloader
INFO 2025-10-29 15:15:38,925 basehttp 82 140189606344384 "GET / HTTP/1.1" 302 0
INFO 2025-10-29 15:16:14,127 basehttp 82 140189606344384 "GET /admin/ HTTP/1.1" 302 0
WARNING 2025-10-29 15:16:41,578 log 82 140189586413248 Not Found: /ws/notifications/1fac988f-cc7b-47db-91a8-bed0b0e008c8/
WARNING 2025-10-29 15:16:41,579 basehttp 82 140189586413248 "GET /ws/notifications/1fac988f-cc7b-47db-91a8-bed0b0e008c8/ HTTP/1.1" 404 6422
WARNING 2025-10-29 15:16:41,786 log 82 140189606344384 Not Found: /favicon.ico
WARNING 2025-10-29 15:16:41,787 basehttp 82 140189606344384 "GET /favicon.ico HTTP/1.1" 404 6293
INFO 2025-10-29 15:16:47,049 basehttp 82 140189606344384 "GET / HTTP/1.1" 302 0
INFO 2025-10-29 15:16:47,348 basehttp 82 140189606344384 "GET /accounts/login/?next=/ HTTP/1.1" 200 2560
INFO 2025-10-29 15:17:57,614 basehttp 82 140189606344384 "POST /accounts/login/ HTTP/1.1" 200 2758
INFO 2025-10-29 15:18:04,382 basehttp 82 140189606344384 "GET /accounts/login/ HTTP/1.1" 200 2508
INFO 2025-10-29 15:18:17,452 basehttp 82 140189606344384 "POST /accounts/login/ HTTP/1.1" 200 2698
ERROR 2025-10-29 15:19:46,470 log 82 140189594805952 Internal Server Error: /accounts/login/
Traceback (most recent call last):
  File "/app/.venv/lib/python3.13/site-packages/django/core/handlers/exception.py", line 55, in inner
    response = get_response(request)
  File "/app/.venv/lib/python3.13/site-packages/django/core/handlers/base.py", line 197, in _get_response
    response = wrapped_callback(request, *callback_args, **callback_kwargs)
  File "/app/.venv/lib/python3.13/site-packages/django/views/generic/base.py", line 105, in view
    return self.dispatch(request, *args, **kwargs)
           ~~~~~~~~~~~~~^^^^^^^^^^^^^^^^^^^^^^^^^^
  File "/app/.venv/lib/python3.13/site-packages/django/utils/decorators.py", line 48, in _wrapper
    return bound_method(*args, **kwargs)
  File "/app/.venv/lib/python3.13/site-packages/allauth/decorators.py", line 12, in wrap
    resp = function(request, *args, **kwargs)
  File "/app/.venv/lib/python3.13/site-packages/django/utils/decorators.py", line 48, in _wrapper
    return bound_method(*args, **kwargs)
  File "/app/.venv/lib/python3.13/site-packages/django/utils/decorators.py", line 48, in _wrapper
    return bound_method(*args, **kwargs)
  File "/app/.venv/lib/python3.13/site-packages/django/views/decorators/debug.py", line 143, in sensitive_post_parameters_wrapper
    return view(request, *args, **kwargs)
  File "/app/.venv/lib/python3.13/site-packages/django/utils/decorators.py", line 48, in _wrapper
    return bound_method(*args, **kwargs)
  File "/app/.venv/lib/python3.13/site-packages/django/views/decorators/cache.py", line 80, in _view_wrapper
    response = view_func(request, *args, **kwargs)
  File "/app/.venv/lib/python3.13/site-packages/allauth/account/views.py", line 95, in dispatch
    return super().dispatch(request, *args, **kwargs)
           ~~~~~~~~~~~~~~~~^^^^^^^^^^^^^^^^^^^^^^^^^^
  File "/app/.venv/lib/python3.13/site-packages/django/utils/decorators.py", line 48, in _wrapper
    return bound_method(*args, **kwargs)
  File "/app/.venv/lib/python3.13/site-packages/django/utils/decorators.py", line 48, in _wrapper
    return bound_method(*args, **kwargs)
  File "/app/.venv/lib/python3.13/site-packages/django/views/decorators/cache.py", line 80, in _view_wrapper
    response = view_func(request, *args, **kwargs)
  File "/app/.venv/lib/python3.13/site-packages/allauth/account/mixins.py", line 53, in dispatch
    response = super().dispatch(request, *args, **kwargs)
  File "/app/.venv/lib/python3.13/site-packages/django/views/generic/base.py", line 144, in dispatch
    return handler(request, *args, **kwargs)
  File "/app/.venv/lib/python3.13/site-packages/allauth/account/mixins.py", line 82, in post
    response = self.form_valid(form)
  File "/app/.venv/lib/python3.13/site-packages/allauth/account/views.py", line 108, in form_valid
    return form.login(self.request, redirect_url=redirect_url)
           ~~~~~~~~~~^^^^^^^^^^^^^^^^^^^^^^^^^^^^^^^^^^^^^^^^^
  File "/app/.venv/lib/python3.13/site-packages/allauth/account/forms.py", line 230, in login
    return self._login_with_password(request, redirect_url, credentials)
           ~~~~~~~~~~~~~~~~~~~~~~~~~^^^^^^^^^^^^^^^^^^^^^^^^^^^^^^^^^^^^
  File "/app/.venv/lib/python3.13/site-packages/allauth/account/forms.py", line 252, in _login_with_password
    ret = flows.login.perform_password_login(request, credentials, login)
  File "/app/.venv/lib/python3.13/site-packages/allauth/account/internal/flows/login.py", line 83, in perform_password_login
    return perform_login(request, login)
  File "/app/.venv/lib/python3.13/site-packages/allauth/account/internal/flows/login.py", line 93, in perform_login
    return resume_login(request, login)
  File "/app/.venv/lib/python3.13/site-packages/allauth/account/internal/flows/login.py", line 102, in resume_login
    response = ctrl.handle()
  File "/app/.venv/lib/python3.13/site-packages/allauth/account/stages.py", line 120, in handle
    response, cont = stage.handle()
                     ~~~~~~~~~~~~^^
  File "/app/.venv/lib/python3.13/site-packages/allauth/account/stages.py", line 158, in handle
    send_verification_email_at_login(self.request, login)
    ~~~~~~~~~~~~~~~~~~~~~~~~~~~~~~~~^^^^^^^^^^^^^^^^^^^^^
  File "/app/.venv/lib/python3.13/site-packages/allauth/account/internal/flows/email_verification.py", line 294, in send_verification_email_at_login
    sent = send_verification_email_at_real_login(request, login)
  File "/app/.venv/lib/python3.13/site-packages/allauth/account/internal/flows/email_verification.py", line 308, in send_verification_email_at_real_login
    return send_verification_email_to_address(request, address, signup=login.signup)
  File "/app/.venv/lib/python3.13/site-packages/allauth/account/internal/flows/email_verification.py", line 269, in send_verification_email_to_address
    confirmation = address.send_confirmation(request, signup=signup)
  File "/app/.venv/lib/python3.13/site-packages/allauth/account/models.py", line 104, in send_confirmation
    confirmation.send(request, signup=signup)
    ~~~~~~~~~~~~~~~~~^^^^^^^^^^^^^^^^^^^^^^^^
  File "/app/.venv/lib/python3.13/site-packages/allauth/account/models.py", line 133, in send
    get_adapter().send_confirmation_mail(request, self, signup)
    ~~~~~~~~~~~~~~~~~~~~~~~~~~~~~~~~~~~~^^^^^^^^^^^^^^^^^^^^^^^
  File "/app/.venv/lib/python3.13/site-packages/allauth/account/adapter.py", line 683, in send_confirmation_mail
    self.send_mail(email_template, emailconfirmation.email_address.email, ctx)
    ~~~~~~~~~~~~~~^^^^^^^^^^^^^^^^^^^^^^^^^^^^^^^^^^^^^^^^^^^^^^^^^^^^^^^^^^^^
  File "/app/users/adapters.py", line 46, in send_mail
    return super().send_mail(template_prefix, email, context)
           ~~~~~~~~~~~~~~~~~^^^^^^^^^^^^^^^^^^^^^^^^^^^^^^^^^
  File "/app/.venv/lib/python3.13/site-packages/allauth/account/adapter.py", line 214, in send_mail
    msg.send()
    ~~~~~~~~^^
  File "/app/.venv/lib/python3.13/site-packages/django/core/mail/message.py", line 307, in send
    return self.get_connection(fail_silently).send_messages([self])
           ~~~~~~~~~~~~~~~~~~~~~~~~~~~~~~~~~~~~~~~~~~~~~~~~^^^^^^^^
  File "/app/.venv/lib/python3.13/site-packages/django/core/mail/backends/smtp.py", line 128, in send_messages
    new_conn_created = self.open()
  File "/app/.venv/lib/python3.13/site-packages/django/core/mail/backends/smtp.py", line 86, in open
    self.connection = self.connection_class(
                      ~~~~~~~~~~~~~~~~~~~~~^
        self.host, self.port, **connection_params
        ^^^^^^^^^^^^^^^^^^^^^^^^^^^^^^^^^^^^^^^^^
    )
    ^
  File "/usr/local/lib/python3.13/smtplib.py", line 264, in __init__
    (code, msg) = self.connect(host, port)
                  ~~~~~~~~~~~~^^^^^^^^^^^^
  File "/usr/local/lib/python3.13/smtplib.py", line 350, in connect
    self.sock = self._get_socket(host, port, self.timeout)
                ~~~~~~~~~~~~~~~~^^^^^^^^^^^^^^^^^^^^^^^^^^
  File "/usr/local/lib/python3.13/smtplib.py", line 321, in _get_socket
    return socket.create_connection((host, port), timeout,
           ~~~~~~~~~~~~~~~~~~~~~~~~^^^^^^^^^^^^^^^^^^^^^^^
                                    self.source_address)
                                    ^^^^^^^^^^^^^^^^^^^^
  File "/usr/local/lib/python3.13/socket.py", line 864, in create_connection
    raise exceptions[0]
  File "/usr/local/lib/python3.13/socket.py", line 849, in create_connection
    sock.connect(sa)
    ~~~~~~~~~~~~^^^^
ConnectionRefusedError: [Errno 111] Connection refused
ERROR 2025-10-29 15:19:46,540 basehttp 82 140189594805952 "POST /accounts/login/ HTTP/1.1" 500 251731
INFO 2025-10-29 15:21:13,937 autoreload 82 140189919349696 /app/crm/settings.py changed, reloading.
INFO 2025-10-29 15:21:34,312 autoreload 10 139657322646464 Watching for file changes with StatReloader
INFO 2025-10-29 15:22:52,079 basehttp 10 139657210754752 "GET / HTTP/1.1" 302 0
INFO 2025-10-29 15:22:52,350 basehttp 10 139657210754752 "GET /accounts/login/?next=/ HTTP/1.1" 200 2560
INFO 2025-10-29 15:23:02,448 basehttp 10 139657210754752 "POST /accounts/login/ HTTP/1.1" 200 2758
INFO 2025-10-29 15:23:19,446 basehttp 10 139657210754752 "GET /accounts/signup/?next=%2F HTTP/1.1" 200 2965
INFO 2025-10-29 15:23:23,344 basehttp 10 139657210754752 "GET /accounts/login/?next=%2F HTTP/1.1" 200 2560
INFO 2025-10-29 15:23:39,637 basehttp 10 139657210754752 "POST /accounts/login/ HTTP/1.1" 200 2758
INFO 2025-10-29 15:23:59,109 basehttp 10 139657210754752 "POST /accounts/login/ HTTP/1.1" 302 0
ERROR 2025-10-29 15:23:59,282 log 10 139657210754752 Internal Server Error: /
Traceback (most recent call last):
  File "/app/.venv/lib/python3.13/site-packages/django/core/handlers/exception.py", line 55, in inner
    response = get_response(request)
  File "/app/.venv/lib/python3.13/site-packages/django/core/handlers/base.py", line 197, in _get_response
    response = wrapped_callback(request, *callback_args, **callback_kwargs)
  File "/app/.venv/lib/python3.13/site-packages/django/views/generic/base.py", line 105, in view
    return self.dispatch(request, *args, **kwargs)
           ~~~~~~~~~~~~~^^^^^^^^^^^^^^^^^^^^^^^^^^
  File "/app/.venv/lib/python3.13/site-packages/django/contrib/auth/mixins.py", line 73, in dispatch
    return super().dispatch(request, *args, **kwargs)
           ~~~~~~~~~~~~~~~~^^^^^^^^^^^^^^^^^^^^^^^^^^
  File "/app/.venv/lib/python3.13/site-packages/django/views/generic/base.py", line 144, in dispatch
    return handler(request, *args, **kwargs)
  File "/app/.venv/lib/python3.13/site-packages/django/views/generic/base.py", line 228, in get
    context = self.get_context_data(**kwargs)
  File "/app/users/views.py", line 51, in get_context_data
    context["stats"] = self.get_dashboard_stats()
                       ~~~~~~~~~~~~~~~~~~~~~~~~^^
  File "/app/users/views.py", line 81, in get_dashboard_stats
    .filter(Q(is_email_verified=True) | Q(is_phone_verified=True))
     ~~~~~~^^^^^^^^^^^^^^^^^^^^^^^^^^^^^^^^^^^^^^^^^^^^^^^^^^^^^^^
  File "/app/.venv/lib/python3.13/site-packages/django/db/models/query.py", line 1493, in filter
    return self._filter_or_exclude(False, args, kwargs)
           ~~~~~~~~~~~~~~~~~~~~~~~^^^^^^^^^^^^^^^^^^^^^
  File "/app/.venv/lib/python3.13/site-packages/django/db/models/query.py", line 1511, in _filter_or_exclude
    clone._filter_or_exclude_inplace(negate, args, kwargs)
    ~~~~~~~~~~~~~~~~~~~~~~~~~~~~~~~~^^^^^^^^^^^^^^^^^^^^^^
  File "/app/.venv/lib/python3.13/site-packages/django/db/models/query.py", line 1518, in _filter_or_exclude_inplace
    self._query.add_q(Q(*args, **kwargs))
    ~~~~~~~~~~~~~~~~~^^^^^^^^^^^^^^^^^^^^
  File "/app/.venv/lib/python3.13/site-packages/django/db/models/sql/query.py", line 1646, in add_q
    clause, _ = self._add_q(q_object, can_reuse)
                ~~~~~~~~~~~^^^^^^^^^^^^^^^^^^^^^
  File "/app/.venv/lib/python3.13/site-packages/django/db/models/sql/query.py", line 1678, in _add_q
    child_clause, needed_inner = self.build_filter(
                                 ~~~~~~~~~~~~~~~~~^
        child,
        ^^^^^^
    ...<7 lines>...
        update_join_types=update_join_types,
        ^^^^^^^^^^^^^^^^^^^^^^^^^^^^^^^^^^^^
    )
    ^
  File "/app/.venv/lib/python3.13/site-packages/django/db/models/sql/query.py", line 1503, in build_filter
    return self._add_q(
           ~~~~~~~~~~~^
        filter_expr,
        ^^^^^^^^^^^^
    ...<7 lines>...
        update_join_types=update_join_types,
        ^^^^^^^^^^^^^^^^^^^^^^^^^^^^^^^^^^^^
    )
    ^
  File "/app/.venv/lib/python3.13/site-packages/django/db/models/sql/query.py", line 1678, in _add_q
    child_clause, needed_inner = self.build_filter(
                                 ~~~~~~~~~~~~~~~~~^
        child,
        ^^^^^^
    ...<7 lines>...
        update_join_types=update_join_types,
        ^^^^^^^^^^^^^^^^^^^^^^^^^^^^^^^^^^^^
    )
    ^
  File "/app/.venv/lib/python3.13/site-packages/django/db/models/sql/query.py", line 1526, in build_filter
    lookups, parts, reffed_expression = self.solve_lookup_type(arg, summarize)
                                        ~~~~~~~~~~~~~~~~~~~~~~^^^^^^^^^^^^^^^^
  File "/app/.venv/lib/python3.13/site-packages/django/db/models/sql/query.py", line 1333, in solve_lookup_type
    _, field, _, lookup_parts = self.names_to_path(lookup_splitted, self.get_meta())
                                ~~~~~~~~~~~~~~~~~~^^^^^^^^^^^^^^^^^^^^^^^^^^^^^^^^^^
  File "/app/.venv/lib/python3.13/site-packages/django/db/models/sql/query.py", line 1806, in names_to_path
    raise FieldError(
    ...<2 lines>...
    )
django.core.exceptions.FieldError: Cannot resolve keyword 'is_email_verified' into field. Choices are: address, company, created_at, email, first_name, groups, id, interactions, is_active, is_favorite, last_name, linkedin, notes, phone, position, projects, tags, telegram, updated_at, user, user_id, website, whatsapp
ERROR 2025-10-29 15:23:59,320 basehttp 10 139657210754752 "GET / HTTP/1.1" 500 146346
INFO 2025-10-29 15:25:37,976 autoreload 11 140260839484352 Watching for file changes with StatReloader
ERROR 2025-10-29 15:26:08,635 log 11 140260659951296 Internal Server Error: /
Traceback (most recent call last):
  File "/app/.venv/lib/python3.13/site-packages/django/core/handlers/exception.py", line 55, in inner
    response = get_response(request)
  File "/app/.venv/lib/python3.13/site-packages/django/core/handlers/base.py", line 197, in _get_response
    response = wrapped_callback(request, *callback_args, **callback_kwargs)
  File "/app/.venv/lib/python3.13/site-packages/django/views/generic/base.py", line 105, in view
    return self.dispatch(request, *args, **kwargs)
           ~~~~~~~~~~~~~^^^^^^^^^^^^^^^^^^^^^^^^^^
  File "/app/.venv/lib/python3.13/site-packages/django/contrib/auth/mixins.py", line 73, in dispatch
    return super().dispatch(request, *args, **kwargs)
           ~~~~~~~~~~~~~~~~^^^^^^^^^^^^^^^^^^^^^^^^^^
  File "/app/.venv/lib/python3.13/site-packages/django/views/generic/base.py", line 144, in dispatch
    return handler(request, *args, **kwargs)
  File "/app/.venv/lib/python3.13/site-packages/django/views/generic/base.py", line 228, in get
    context = self.get_context_data(**kwargs)
  File "/app/users/views.py", line 51, in get_context_data
    context["stats"] = self.get_dashboard_stats()
                       ~~~~~~~~~~~~~~~~~~~~~~~~^^
  File "/app/users/views.py", line 81, in get_dashboard_stats
    .filter(Q(is_email_verified=True) | Q(is_phone_verified=True))
     ~~~~~~^^^^^^^^^^^^^^^^^^^^^^^^^^^^^^^^^^^^^^^^^^^^^^^^^^^^^^^
  File "/app/.venv/lib/python3.13/site-packages/django/db/models/query.py", line 1493, in filter
    return self._filter_or_exclude(False, args, kwargs)
           ~~~~~~~~~~~~~~~~~~~~~~~^^^^^^^^^^^^^^^^^^^^^
  File "/app/.venv/lib/python3.13/site-packages/django/db/models/query.py", line 1511, in _filter_or_exclude
    clone._filter_or_exclude_inplace(negate, args, kwargs)
    ~~~~~~~~~~~~~~~~~~~~~~~~~~~~~~~~^^^^^^^^^^^^^^^^^^^^^^
  File "/app/.venv/lib/python3.13/site-packages/django/db/models/query.py", line 1518, in _filter_or_exclude_inplace
    self._query.add_q(Q(*args, **kwargs))
    ~~~~~~~~~~~~~~~~~^^^^^^^^^^^^^^^^^^^^
  File "/app/.venv/lib/python3.13/site-packages/django/db/models/sql/query.py", line 1646, in add_q
    clause, _ = self._add_q(q_object, can_reuse)
                ~~~~~~~~~~~^^^^^^^^^^^^^^^^^^^^^
  File "/app/.venv/lib/python3.13/site-packages/django/db/models/sql/query.py", line 1678, in _add_q
    child_clause, needed_inner = self.build_filter(
                                 ~~~~~~~~~~~~~~~~~^
        child,
        ^^^^^^
    ...<7 lines>...
        update_join_types=update_join_types,
        ^^^^^^^^^^^^^^^^^^^^^^^^^^^^^^^^^^^^
    )
    ^
  File "/app/.venv/lib/python3.13/site-packages/django/db/models/sql/query.py", line 1503, in build_filter
    return self._add_q(
           ~~~~~~~~~~~^
        filter_expr,
        ^^^^^^^^^^^^
    ...<7 lines>...
        update_join_types=update_join_types,
        ^^^^^^^^^^^^^^^^^^^^^^^^^^^^^^^^^^^^
    )
    ^
  File "/app/.venv/lib/python3.13/site-packages/django/db/models/sql/query.py", line 1678, in _add_q
    child_clause, needed_inner = self.build_filter(
                                 ~~~~~~~~~~~~~~~~~^
        child,
        ^^^^^^
    ...<7 lines>...
        update_join_types=update_join_types,
        ^^^^^^^^^^^^^^^^^^^^^^^^^^^^^^^^^^^^
    )
    ^
  File "/app/.venv/lib/python3.13/site-packages/django/db/models/sql/query.py", line 1526, in build_filter
    lookups, parts, reffed_expression = self.solve_lookup_type(arg, summarize)
                                        ~~~~~~~~~~~~~~~~~~~~~~^^^^^^^^^^^^^^^^
  File "/app/.venv/lib/python3.13/site-packages/django/db/models/sql/query.py", line 1333, in solve_lookup_type
    _, field, _, lookup_parts = self.names_to_path(lookup_splitted, self.get_meta())
                                ~~~~~~~~~~~~~~~~~~^^^^^^^^^^^^^^^^^^^^^^^^^^^^^^^^^^
  File "/app/.venv/lib/python3.13/site-packages/django/db/models/sql/query.py", line 1806, in names_to_path
    raise FieldError(
    ...<2 lines>...
    )
django.core.exceptions.FieldError: Cannot resolve keyword 'is_email_verified' into field. Choices are: address, company, created_at, email, first_name, groups, id, interactions, is_active, is_favorite, last_name, linkedin, notes, phone, position, projects, tags, telegram, updated_at, user, user_id, website, whatsapp
ERROR 2025-10-29 15:26:08,672 basehttp 11 140260659951296 "GET / HTTP/1.1" 500 146180
ERROR 2025-10-29 15:26:20,858 log 11 140260659951296 Internal Server Error: /
Traceback (most recent call last):
  File "/app/.venv/lib/python3.13/site-packages/django/core/handlers/exception.py", line 55, in inner
    response = get_response(request)
  File "/app/.venv/lib/python3.13/site-packages/django/core/handlers/base.py", line 197, in _get_response
    response = wrapped_callback(request, *callback_args, **callback_kwargs)
  File "/app/.venv/lib/python3.13/site-packages/django/views/generic/base.py", line 105, in view
    return self.dispatch(request, *args, **kwargs)
           ~~~~~~~~~~~~~^^^^^^^^^^^^^^^^^^^^^^^^^^
  File "/app/.venv/lib/python3.13/site-packages/django/contrib/auth/mixins.py", line 73, in dispatch
    return super().dispatch(request, *args, **kwargs)
           ~~~~~~~~~~~~~~~~^^^^^^^^^^^^^^^^^^^^^^^^^^
  File "/app/.venv/lib/python3.13/site-packages/django/views/generic/base.py", line 144, in dispatch
    return handler(request, *args, **kwargs)
  File "/app/.venv/lib/python3.13/site-packages/django/views/generic/base.py", line 228, in get
    context = self.get_context_data(**kwargs)
  File "/app/users/views.py", line 51, in get_context_data
    context["stats"] = self.get_dashboard_stats()
                       ~~~~~~~~~~~~~~~~~~~~~~~~^^
  File "/app/users/views.py", line 81, in get_dashboard_stats
    .filter(Q(is_email_verified=True) | Q(is_phone_verified=True))
     ~~~~~~^^^^^^^^^^^^^^^^^^^^^^^^^^^^^^^^^^^^^^^^^^^^^^^^^^^^^^^
  File "/app/.venv/lib/python3.13/site-packages/django/db/models/query.py", line 1493, in filter
    return self._filter_or_exclude(False, args, kwargs)
           ~~~~~~~~~~~~~~~~~~~~~~~^^^^^^^^^^^^^^^^^^^^^
  File "/app/.venv/lib/python3.13/site-packages/django/db/models/query.py", line 1511, in _filter_or_exclude
    clone._filter_or_exclude_inplace(negate, args, kwargs)
    ~~~~~~~~~~~~~~~~~~~~~~~~~~~~~~~~^^^^^^^^^^^^^^^^^^^^^^
  File "/app/.venv/lib/python3.13/site-packages/django/db/models/query.py", line 1518, in _filter_or_exclude_inplace
    self._query.add_q(Q(*args, **kwargs))
    ~~~~~~~~~~~~~~~~~^^^^^^^^^^^^^^^^^^^^
  File "/app/.venv/lib/python3.13/site-packages/django/db/models/sql/query.py", line 1646, in add_q
    clause, _ = self._add_q(q_object, can_reuse)
                ~~~~~~~~~~~^^^^^^^^^^^^^^^^^^^^^
  File "/app/.venv/lib/python3.13/site-packages/django/db/models/sql/query.py", line 1678, in _add_q
    child_clause, needed_inner = self.build_filter(
                                 ~~~~~~~~~~~~~~~~~^
        child,
        ^^^^^^
    ...<7 lines>...
        update_join_types=update_join_types,
        ^^^^^^^^^^^^^^^^^^^^^^^^^^^^^^^^^^^^
    )
    ^
  File "/app/.venv/lib/python3.13/site-packages/django/db/models/sql/query.py", line 1503, in build_filter
    return self._add_q(
           ~~~~~~~~~~~^
        filter_expr,
        ^^^^^^^^^^^^
    ...<7 lines>...
        update_join_types=update_join_types,
        ^^^^^^^^^^^^^^^^^^^^^^^^^^^^^^^^^^^^
    )
    ^
  File "/app/.venv/lib/python3.13/site-packages/django/db/models/sql/query.py", line 1678, in _add_q
    child_clause, needed_inner = self.build_filter(
                                 ~~~~~~~~~~~~~~~~~^
        child,
        ^^^^^^
    ...<7 lines>...
        update_join_types=update_join_types,
        ^^^^^^^^^^^^^^^^^^^^^^^^^^^^^^^^^^^^
    )
    ^
  File "/app/.venv/lib/python3.13/site-packages/django/db/models/sql/query.py", line 1526, in build_filter
    lookups, parts, reffed_expression = self.solve_lookup_type(arg, summarize)
                                        ~~~~~~~~~~~~~~~~~~~~~~^^^^^^^^^^^^^^^^
  File "/app/.venv/lib/python3.13/site-packages/django/db/models/sql/query.py", line 1333, in solve_lookup_type
    _, field, _, lookup_parts = self.names_to_path(lookup_splitted, self.get_meta())
                                ~~~~~~~~~~~~~~~~~~^^^^^^^^^^^^^^^^^^^^^^^^^^^^^^^^^^
  File "/app/.venv/lib/python3.13/site-packages/django/db/models/sql/query.py", line 1806, in names_to_path
    raise FieldError(
    ...<2 lines>...
    )
django.core.exceptions.FieldError: Cannot resolve keyword 'is_email_verified' into field. Choices are: address, company, created_at, email, first_name, groups, id, interactions, is_active, is_favorite, last_name, linkedin, notes, phone, position, projects, tags, telegram, updated_at, user, user_id, website, whatsapp
ERROR 2025-10-29 15:26:20,872 basehttp 11 140260659951296 "GET / HTTP/1.1" 500 146043
INFO 2025-10-29 15:40:59,031 autoreload 11 140260839484352 /app/contacts/models.py changed, reloading.
INFO 2025-10-29 15:49:58,271 autoreload 95 140286474935232 Watching for file changes with StatReloader
ERROR 2025-10-29 15:50:58,115 log 95 140286295537344 Internal Server Error: /
Traceback (most recent call last):
  File "/app/.venv/lib/python3.13/site-packages/django/db/backends/utils.py", line 105, in _execute
    return self.cursor.execute(sql, params)
           ~~~~~~~~~~~~~~~~~~~^^^^^^^^^^^^^
psycopg2.errors.UndefinedColumn: column contacts_contact.is_email_verified does not exist
LINE 1: ...'164822ac-d15c-45f0-b58f-4a6eae0f703d'::uuid AND ("contacts_...
                                                             ^


The above exception was the direct cause of the following exception:

Traceback (most recent call last):
  File "/app/.venv/lib/python3.13/site-packages/django/core/handlers/exception.py", line 55, in inner
    response = get_response(request)
  File "/app/.venv/lib/python3.13/site-packages/django/core/handlers/base.py", line 197, in _get_response
    response = wrapped_callback(request, *callback_args, **callback_kwargs)
  File "/app/.venv/lib/python3.13/site-packages/django/views/generic/base.py", line 105, in view
    return self.dispatch(request, *args, **kwargs)
           ~~~~~~~~~~~~~^^^^^^^^^^^^^^^^^^^^^^^^^^
  File "/app/.venv/lib/python3.13/site-packages/django/contrib/auth/mixins.py", line 73, in dispatch
    return super().dispatch(request, *args, **kwargs)
           ~~~~~~~~~~~~~~~~^^^^^^^^^^^^^^^^^^^^^^^^^^
  File "/app/.venv/lib/python3.13/site-packages/django/views/generic/base.py", line 144, in dispatch
    return handler(request, *args, **kwargs)
  File "/app/.venv/lib/python3.13/site-packages/django/views/generic/base.py", line 228, in get
    context = self.get_context_data(**kwargs)
  File "/app/users/views.py", line 51, in get_context_data
    context["stats"] = self.get_dashboard_stats()
                       ~~~~~~~~~~~~~~~~~~~~~~~~^^
  File "/app/users/views.py", line 82, in get_dashboard_stats
    .count(),
     ~~~~~^^
  File "/app/.venv/lib/python3.13/site-packages/django/db/models/query.py", line 604, in count
    return self.query.get_count(using=self.db)
           ~~~~~~~~~~~~~~~~~~~~^^^^^^^^^^^^^^^
  File "/app/.venv/lib/python3.13/site-packages/django/db/models/sql/query.py", line 644, in get_count
    return obj.get_aggregation(using, {"__count": Count("*")})["__count"]
           ~~~~~~~~~~~~~~~~~~~^^^^^^^^^^^^^^^^^^^^^^^^^^^^^^^^
  File "/app/.venv/lib/python3.13/site-packages/django/db/models/sql/query.py", line 626, in get_aggregation
    result = compiler.execute_sql(SINGLE)
  File "/app/.venv/lib/python3.13/site-packages/django/db/models/sql/compiler.py", line 1623, in execute_sql
    cursor.execute(sql, params)
    ~~~~~~~~~~~~~~^^^^^^^^^^^^^
  File "/app/.venv/lib/python3.13/site-packages/django/db/backends/utils.py", line 122, in execute
    return super().execute(sql, params)
           ~~~~~~~~~~~~~~~^^^^^^^^^^^^^
  File "/app/.venv/lib/python3.13/site-packages/django/db/backends/utils.py", line 79, in execute
    return self._execute_with_wrappers(
           ~~~~~~~~~~~~~~~~~~~~~~~~~~~^
        sql, params, many=False, executor=self._execute
        ^^^^^^^^^^^^^^^^^^^^^^^^^^^^^^^^^^^^^^^^^^^^^^^
    )
    ^
  File "/app/.venv/lib/python3.13/site-packages/django/db/backends/utils.py", line 92, in _execute_with_wrappers
    return executor(sql, params, many, context)
  File "/app/.venv/lib/python3.13/site-packages/django/db/backends/utils.py", line 100, in _execute
    with self.db.wrap_database_errors:
         ^^^^^^^^^^^^^^^^^^^^^^^^^^^^
  File "/app/.venv/lib/python3.13/site-packages/django/db/utils.py", line 91, in __exit__
    raise dj_exc_value.with_traceback(traceback) from exc_value
  File "/app/.venv/lib/python3.13/site-packages/django/db/backends/utils.py", line 105, in _execute
    return self.cursor.execute(sql, params)
           ~~~~~~~~~~~~~~~~~~~^^^^^^^^^^^^^
django.db.utils.ProgrammingError: column contacts_contact.is_email_verified does not exist
LINE 1: ...'164822ac-d15c-45f0-b58f-4a6eae0f703d'::uuid AND ("contacts_...
                                                             ^

ERROR 2025-10-29 15:50:58,167 basehttp 95 140286295537344 "GET / HTTP/1.1" 500 150145
INFO 2025-10-29 15:55:14,065 autoreload 11 140231437990848 Watching for file changes with StatReloader
INFO 2025-10-29 15:56:17,667 autoreload 10 139665843309504 Watching for file changes with StatReloader
ERROR 2025-10-29 15:56:23,351 log 10 139665732531904 Internal Server Error: /
Traceback (most recent call last):
  File "/app/.venv/lib/python3.13/site-packages/django/core/handlers/exception.py", line 55, in inner
    response = get_response(request)
  File "/app/.venv/lib/python3.13/site-packages/django/core/handlers/base.py", line 220, in _get_response
    response = response.render()
  File "/app/.venv/lib/python3.13/site-packages/django/template/response.py", line 114, in render
    self.content = self.rendered_content
                   ^^^^^^^^^^^^^^^^^^^^^
  File "/app/.venv/lib/python3.13/site-packages/django/template/response.py", line 92, in rendered_content
    return template.render(context, self._request)
           ~~~~~~~~~~~~~~~^^^^^^^^^^^^^^^^^^^^^^^^
  File "/app/.venv/lib/python3.13/site-packages/django/template/backends/django.py", line 107, in render
    return self.template.render(context)
           ~~~~~~~~~~~~~~~~~~~~^^^^^^^^^
  File "/app/.venv/lib/python3.13/site-packages/django/template/base.py", line 171, in render
    return self._render(context)
           ~~~~~~~~~~~~^^^^^^^^^
  File "/app/.venv/lib/python3.13/site-packages/django/template/base.py", line 163, in _render
    return self.nodelist.render(context)
           ~~~~~~~~~~~~~~~~~~~~^^^^^^^^^
  File "/app/.venv/lib/python3.13/site-packages/django/template/base.py", line 1016, in render
    return SafeString("".join([node.render_annotated(context) for node in self]))
                               ~~~~~~~~~~~~~~~~~~~~~^^^^^^^^^
  File "/app/.venv/lib/python3.13/site-packages/django/template/base.py", line 977, in render_annotated
    return self.render(context)
           ~~~~~~~~~~~^^^^^^^^^
  File "/app/.venv/lib/python3.13/site-packages/django/template/loader_tags.py", line 159, in render
    return compiled_parent._render(context)
           ~~~~~~~~~~~~~~~~~~~~~~~^^^^^^^^^
  File "/app/.venv/lib/python3.13/site-packages/django/template/base.py", line 163, in _render
    return self.nodelist.render(context)
           ~~~~~~~~~~~~~~~~~~~~^^^^^^^^^
  File "/app/.venv/lib/python3.13/site-packages/django/template/base.py", line 1016, in render
    return SafeString("".join([node.render_annotated(context) for node in self]))
                               ~~~~~~~~~~~~~~~~~~~~~^^^^^^^^^
  File "/app/.venv/lib/python3.13/site-packages/django/template/base.py", line 977, in render_annotated
    return self.render(context)
           ~~~~~~~~~~~^^^^^^^^^
  File "/app/.venv/lib/python3.13/site-packages/django/template/loader_tags.py", line 65, in render
    result = block.nodelist.render(context)
  File "/app/.venv/lib/python3.13/site-packages/django/template/base.py", line 1016, in render
    return SafeString("".join([node.render_annotated(context) for node in self]))
                               ~~~~~~~~~~~~~~~~~~~~~^^^^^^^^^
  File "/app/.venv/lib/python3.13/site-packages/django/template/base.py", line 977, in render_annotated
    return self.render(context)
           ~~~~~~~~~~~^^^^^^^^^
  File "/app/.venv/lib/python3.13/site-packages/django/template/defaulttags.py", line 480, in render
    url = reverse(view_name, args=args, kwargs=kwargs, current_app=current_app)
  File "/app/.venv/lib/python3.13/site-packages/django/urls/base.py", line 98, in reverse
    resolved_url = resolver._reverse_with_prefix(view, prefix, *args, **kwargs)
  File "/app/.venv/lib/python3.13/site-packages/django/urls/resolvers.py", line 831, in _reverse_with_prefix
    raise NoReverseMatch(msg)
django.urls.exceptions.NoReverseMatch: Reverse for 'dashboard' not found. 'dashboard' is not a valid view function or pattern name.
ERROR 2025-10-29 15:56:23,390 basehttp 10 139665732531904 "GET / HTTP/1.1" 500 166152
ERROR 2025-10-29 16:04:18,269 log 10 139665732531904 Internal Server Error: /
Traceback (most recent call last):
  File "/app/.venv/lib/python3.13/site-packages/django/urls/base.py", line 81, in reverse
    extra, resolver = resolver.namespace_dict[ns]
                      ~~~~~~~~~~~~~~~~~~~~~~~^^^^
KeyError: 'emails'

During handling of the above exception, another exception occurred:

Traceback (most recent call last):
  File "/app/.venv/lib/python3.13/site-packages/django/core/handlers/exception.py", line 55, in inner
    response = get_response(request)
  File "/app/.venv/lib/python3.13/site-packages/django/core/handlers/base.py", line 220, in _get_response
    response = response.render()
  File "/app/.venv/lib/python3.13/site-packages/django/template/response.py", line 114, in render
    self.content = self.rendered_content
                   ^^^^^^^^^^^^^^^^^^^^^
  File "/app/.venv/lib/python3.13/site-packages/django/template/response.py", line 92, in rendered_content
    return template.render(context, self._request)
           ~~~~~~~~~~~~~~~^^^^^^^^^^^^^^^^^^^^^^^^
  File "/app/.venv/lib/python3.13/site-packages/django/template/backends/django.py", line 107, in render
    return self.template.render(context)
           ~~~~~~~~~~~~~~~~~~~~^^^^^^^^^
  File "/app/.venv/lib/python3.13/site-packages/django/template/base.py", line 171, in render
    return self._render(context)
           ~~~~~~~~~~~~^^^^^^^^^
  File "/app/.venv/lib/python3.13/site-packages/django/template/base.py", line 163, in _render
    return self.nodelist.render(context)
           ~~~~~~~~~~~~~~~~~~~~^^^^^^^^^
  File "/app/.venv/lib/python3.13/site-packages/django/template/base.py", line 1016, in render
    return SafeString("".join([node.render_annotated(context) for node in self]))
                               ~~~~~~~~~~~~~~~~~~~~~^^^^^^^^^
  File "/app/.venv/lib/python3.13/site-packages/django/template/base.py", line 977, in render_annotated
    return self.render(context)
           ~~~~~~~~~~~^^^^^^^^^
  File "/app/.venv/lib/python3.13/site-packages/django/template/loader_tags.py", line 159, in render
    return compiled_parent._render(context)
           ~~~~~~~~~~~~~~~~~~~~~~~^^^^^^^^^
  File "/app/.venv/lib/python3.13/site-packages/django/template/base.py", line 163, in _render
    return self.nodelist.render(context)
           ~~~~~~~~~~~~~~~~~~~~^^^^^^^^^
  File "/app/.venv/lib/python3.13/site-packages/django/template/base.py", line 1016, in render
    return SafeString("".join([node.render_annotated(context) for node in self]))
                               ~~~~~~~~~~~~~~~~~~~~~^^^^^^^^^
  File "/app/.venv/lib/python3.13/site-packages/django/template/base.py", line 977, in render_annotated
    return self.render(context)
           ~~~~~~~~~~~^^^^^^^^^
  File "/app/.venv/lib/python3.13/site-packages/django/template/loader_tags.py", line 65, in render
    result = block.nodelist.render(context)
  File "/app/.venv/lib/python3.13/site-packages/django/template/base.py", line 1016, in render
    return SafeString("".join([node.render_annotated(context) for node in self]))
                               ~~~~~~~~~~~~~~~~~~~~~^^^^^^^^^
  File "/app/.venv/lib/python3.13/site-packages/django/template/base.py", line 977, in render_annotated
    return self.render(context)
           ~~~~~~~~~~~^^^^^^^^^
  File "/app/.venv/lib/python3.13/site-packages/django/template/defaulttags.py", line 480, in render
    url = reverse(view_name, args=args, kwargs=kwargs, current_app=current_app)
  File "/app/.venv/lib/python3.13/site-packages/django/urls/base.py", line 92, in reverse
    raise NoReverseMatch("%s is not a registered namespace" % key)
django.urls.exceptions.NoReverseMatch: 'emails' is not a registered namespace
ERROR 2025-10-29 16:04:18,286 basehttp 10 139665732531904 "GET / HTTP/1.1" 500 168640
INFO 2025-10-29 16:05:13,719 autoreload 10 139665843309504 /app/crm/urls.py changed, reloading.
INFO 2025-10-29 16:05:20,038 autoreload 18 139722654731200 Watching for file changes with StatReloader
ERROR 2025-10-29 18:10:09,919 signal 10 140017397779392 Signal handler <bound method DjangoFixup.on_import_modules of <celery.fixups.django.DjangoFixup object at 0x7f585555b4d0>> raised: ModuleNotFoundError("No module named 'contacts.api_urls'")
Traceback (most recent call last):
  File "/app/.venv/lib/python3.13/site-packages/django/core/checks/urls.py", line 136, in check_custom_error_handlers
    handler = resolver.resolve_error_handler(status_code)
  File "/app/.venv/lib/python3.13/site-packages/django/urls/resolvers.py", line 732, in resolve_error_handler
    callback = getattr(self.urlconf_module, "handler%s" % view_type, None)
                       ^^^^^^^^^^^^^^^^^^^
  File "/app/.venv/lib/python3.13/site-packages/django/utils/functional.py", line 47, in __get__
    res = instance.__dict__[self.name] = self.func(instance)
                                         ~~~~~~~~~^^^^^^^^^^
  File "/app/.venv/lib/python3.13/site-packages/django/urls/resolvers.py", line 711, in urlconf_module
    return import_module(self.urlconf_name)
  File "/usr/local/lib/python3.13/importlib/__init__.py", line 88, in import_module
    return _bootstrap._gcd_import(name[level:], package, level)
           ~~~~~~~~~~~~~~~~~~~~~~^^^^^^^^^^^^^^^^^^^^^^^^^^^^^^
  File "<frozen importlib._bootstrap>", line 1387, in _gcd_import
  File "<frozen importlib._bootstrap>", line 1360, in _find_and_load
  File "<frozen importlib._bootstrap>", line 1331, in _find_and_load_unlocked
  File "<frozen importlib._bootstrap>", line 935, in _load_unlocked
  File "<frozen importlib._bootstrap_external>", line 1027, in exec_module
  File "<frozen importlib._bootstrap>", line 488, in _call_with_frames_removed
  File "/app/crm/urls.py", line 32, in <module>
    path("contacts/", include("contacts.api_urls")),
                      ~~~~~~~^^^^^^^^^^^^^^^^^^^^^
  File "/app/.venv/lib/python3.13/site-packages/django/urls/conf.py", line 39, in include
    urlconf_module = import_module(urlconf_module)
  File "/usr/local/lib/python3.13/importlib/__init__.py", line 88, in import_module
    return _bootstrap._gcd_import(name[level:], package, level)
           ~~~~~~~~~~~~~~~~~~~~~~^^^^^^^^^^^^^^^^^^^^^^^^^^^^^^
  File "<frozen importlib._bootstrap>", line 1387, in _gcd_import
  File "<frozen importlib._bootstrap>", line 1360, in _find_and_load
  File "<frozen importlib._bootstrap>", line 1324, in _find_and_load_unlocked
ModuleNotFoundError: No module named 'contacts.api_urls'

During handling of the above exception, another exception occurred:

Traceback (most recent call last):
  File "/app/.venv/lib/python3.13/site-packages/celery/utils/dispatch/signal.py", line 280, in send
    response = receiver(signal=self, sender=sender, **named)
  File "/app/.venv/lib/python3.13/site-packages/celery/fixups/django.py", line 101, in on_import_modules
    self.worker_fixup.validate_models()
    ~~~~~~~~~~~~~~~~~~~~~~~~~~~~~~~~~^^
  File "/app/.venv/lib/python3.13/site-packages/celery/fixups/django.py", line 141, in validate_models
    run_checks()
    ~~~~~~~~~~^^
  File "/app/.venv/lib/python3.13/site-packages/django/core/checks/registry.py", line 89, in run_checks
    new_errors = check(app_configs=app_configs, databases=databases)
  File "/app/.venv/lib/python3.13/site-packages/django/core/checks/urls.py", line 138, in check_custom_error_handlers
    path = getattr(resolver.urlconf_module, "handler%s" % status_code)
                   ^^^^^^^^^^^^^^^^^^^^^^^
  File "/app/.venv/lib/python3.13/site-packages/django/utils/functional.py", line 47, in __get__
    res = instance.__dict__[self.name] = self.func(instance)
                                         ~~~~~~~~~^^^^^^^^^^
  File "/app/.venv/lib/python3.13/site-packages/django/urls/resolvers.py", line 711, in urlconf_module
    return import_module(self.urlconf_name)
  File "/usr/local/lib/python3.13/importlib/__init__.py", line 88, in import_module
    return _bootstrap._gcd_import(name[level:], package, level)
           ~~~~~~~~~~~~~~~~~~~~~~^^^^^^^^^^^^^^^^^^^^^^^^^^^^^^
  File "<frozen importlib._bootstrap>", line 1387, in _gcd_import
  File "<frozen importlib._bootstrap>", line 1360, in _find_and_load
  File "<frozen importlib._bootstrap>", line 1331, in _find_and_load_unlocked
  File "<frozen importlib._bootstrap>", line 935, in _load_unlocked
  File "<frozen importlib._bootstrap_external>", line 1027, in exec_module
  File "<frozen importlib._bootstrap>", line 488, in _call_with_frames_removed
  File "/app/crm/urls.py", line 32, in <module>
    path("contacts/", include("contacts.api_urls")),
                      ~~~~~~~^^^^^^^^^^^^^^^^^^^^^
  File "/app/.venv/lib/python3.13/site-packages/django/urls/conf.py", line 39, in include
    urlconf_module = import_module(urlconf_module)
  File "/usr/local/lib/python3.13/importlib/__init__.py", line 88, in import_module
    return _bootstrap._gcd_import(name[level:], package, level)
           ~~~~~~~~~~~~~~~~~~~~~~^^^^^^^^^^^^^^^^^^^^^^^^^^^^^^
  File "<frozen importlib._bootstrap>", line 1387, in _gcd_import
  File "<frozen importlib._bootstrap>", line 1360, in _find_and_load
  File "<frozen importlib._bootstrap>", line 1324, in _find_and_load_unlocked
ModuleNotFoundError: No module named 'contacts.api_urls'
ERROR 2025-10-29 18:10:22,664 signal 10 139831550913472 Signal handler <bound method DjangoFixup.on_import_modules of <celery.fixups.django.DjangoFixup object at 0x7f2d100234d0>> raised: ModuleNotFoundError("No module named 'contacts.api_urls'")
Traceback (most recent call last):
  File "/app/.venv/lib/python3.13/site-packages/django/core/checks/urls.py", line 136, in check_custom_error_handlers
    handler = resolver.resolve_error_handler(status_code)
  File "/app/.venv/lib/python3.13/site-packages/django/urls/resolvers.py", line 732, in resolve_error_handler
    callback = getattr(self.urlconf_module, "handler%s" % view_type, None)
                       ^^^^^^^^^^^^^^^^^^^
  File "/app/.venv/lib/python3.13/site-packages/django/utils/functional.py", line 47, in __get__
    res = instance.__dict__[self.name] = self.func(instance)
                                         ~~~~~~~~~^^^^^^^^^^
  File "/app/.venv/lib/python3.13/site-packages/django/urls/resolvers.py", line 711, in urlconf_module
    return import_module(self.urlconf_name)
  File "/usr/local/lib/python3.13/importlib/__init__.py", line 88, in import_module
    return _bootstrap._gcd_import(name[level:], package, level)
           ~~~~~~~~~~~~~~~~~~~~~~^^^^^^^^^^^^^^^^^^^^^^^^^^^^^^
  File "<frozen importlib._bootstrap>", line 1387, in _gcd_import
  File "<frozen importlib._bootstrap>", line 1360, in _find_and_load
  File "<frozen importlib._bootstrap>", line 1331, in _find_and_load_unlocked
  File "<frozen importlib._bootstrap>", line 935, in _load_unlocked
  File "<frozen importlib._bootstrap_external>", line 1027, in exec_module
  File "<frozen importlib._bootstrap>", line 488, in _call_with_frames_removed
  File "/app/crm/urls.py", line 32, in <module>
    path("contacts/", include("contacts.api_urls")),
                      ~~~~~~~^^^^^^^^^^^^^^^^^^^^^
  File "/app/.venv/lib/python3.13/site-packages/django/urls/conf.py", line 39, in include
    urlconf_module = import_module(urlconf_module)
  File "/usr/local/lib/python3.13/importlib/__init__.py", line 88, in import_module
    return _bootstrap._gcd_import(name[level:], package, level)
           ~~~~~~~~~~~~~~~~~~~~~~^^^^^^^^^^^^^^^^^^^^^^^^^^^^^^
  File "<frozen importlib._bootstrap>", line 1387, in _gcd_import
  File "<frozen importlib._bootstrap>", line 1360, in _find_and_load
  File "<frozen importlib._bootstrap>", line 1324, in _find_and_load_unlocked
ModuleNotFoundError: No module named 'contacts.api_urls'

During handling of the above exception, another exception occurred:

Traceback (most recent call last):
  File "/app/.venv/lib/python3.13/site-packages/celery/utils/dispatch/signal.py", line 280, in send
    response = receiver(signal=self, sender=sender, **named)
  File "/app/.venv/lib/python3.13/site-packages/celery/fixups/django.py", line 101, in on_import_modules
    self.worker_fixup.validate_models()
    ~~~~~~~~~~~~~~~~~~~~~~~~~~~~~~~~~^^
  File "/app/.venv/lib/python3.13/site-packages/celery/fixups/django.py", line 141, in validate_models
    run_checks()
    ~~~~~~~~~~^^
  File "/app/.venv/lib/python3.13/site-packages/django/core/checks/registry.py", line 89, in run_checks
    new_errors = check(app_configs=app_configs, databases=databases)
  File "/app/.venv/lib/python3.13/site-packages/django/core/checks/urls.py", line 138, in check_custom_error_handlers
    path = getattr(resolver.urlconf_module, "handler%s" % status_code)
                   ^^^^^^^^^^^^^^^^^^^^^^^
  File "/app/.venv/lib/python3.13/site-packages/django/utils/functional.py", line 47, in __get__
    res = instance.__dict__[self.name] = self.func(instance)
                                         ~~~~~~~~~^^^^^^^^^^
  File "/app/.venv/lib/python3.13/site-packages/django/urls/resolvers.py", line 711, in urlconf_module
    return import_module(self.urlconf_name)
  File "/usr/local/lib/python3.13/importlib/__init__.py", line 88, in import_module
    return _bootstrap._gcd_import(name[level:], package, level)
           ~~~~~~~~~~~~~~~~~~~~~~^^^^^^^^^^^^^^^^^^^^^^^^^^^^^^
  File "<frozen importlib._bootstrap>", line 1387, in _gcd_import
  File "<frozen importlib._bootstrap>", line 1360, in _find_and_load
  File "<frozen importlib._bootstrap>", line 1331, in _find_and_load_unlocked
  File "<frozen importlib._bootstrap>", line 935, in _load_unlocked
  File "<frozen importlib._bootstrap_external>", line 1027, in exec_module
  File "<frozen importlib._bootstrap>", line 488, in _call_with_frames_removed
  File "/app/crm/urls.py", line 32, in <module>
    path("contacts/", include("contacts.api_urls")),
                      ~~~~~~~^^^^^^^^^^^^^^^^^^^^^
  File "/app/.venv/lib/python3.13/site-packages/django/urls/conf.py", line 39, in include
    urlconf_module = import_module(urlconf_module)
  File "/usr/local/lib/python3.13/importlib/__init__.py", line 88, in import_module
    return _bootstrap._gcd_import(name[level:], package, level)
           ~~~~~~~~~~~~~~~~~~~~~~^^^^^^^^^^^^^^^^^^^^^^^^^^^^^^
  File "<frozen importlib._bootstrap>", line 1387, in _gcd_import
  File "<frozen importlib._bootstrap>", line 1360, in _find_and_load
  File "<frozen importlib._bootstrap>", line 1324, in _find_and_load_unlocked
ModuleNotFoundError: No module named 'contacts.api_urls'
INFO 2025-10-29 18:10:36,045 autoreload 11 140517802175424 Watching for file changes with StatReloader
ERROR 2025-10-29 18:10:57,692 signal 9 140036589190080 Signal handler <bound method DjangoFixup.on_import_modules of <celery.fixups.django.DjangoFixup object at 0x7f5ccd3d2660>> raised: ModuleNotFoundError("No module named 'contacts.api_urls'")
Traceback (most recent call last):
  File "/app/.venv/lib/python3.13/site-packages/django/core/checks/urls.py", line 136, in check_custom_error_handlers
    handler = resolver.resolve_error_handler(status_code)
  File "/app/.venv/lib/python3.13/site-packages/django/urls/resolvers.py", line 732, in resolve_error_handler
    callback = getattr(self.urlconf_module, "handler%s" % view_type, None)
                       ^^^^^^^^^^^^^^^^^^^
  File "/app/.venv/lib/python3.13/site-packages/django/utils/functional.py", line 47, in __get__
    res = instance.__dict__[self.name] = self.func(instance)
                                         ~~~~~~~~~^^^^^^^^^^
  File "/app/.venv/lib/python3.13/site-packages/django/urls/resolvers.py", line 711, in urlconf_module
    return import_module(self.urlconf_name)
  File "/usr/local/lib/python3.13/importlib/__init__.py", line 88, in import_module
    return _bootstrap._gcd_import(name[level:], package, level)
           ~~~~~~~~~~~~~~~~~~~~~~^^^^^^^^^^^^^^^^^^^^^^^^^^^^^^
  File "<frozen importlib._bootstrap>", line 1387, in _gcd_import
  File "<frozen importlib._bootstrap>", line 1360, in _find_and_load
  File "<frozen importlib._bootstrap>", line 1331, in _find_and_load_unlocked
  File "<frozen importlib._bootstrap>", line 935, in _load_unlocked
  File "<frozen importlib._bootstrap_external>", line 1027, in exec_module
  File "<frozen importlib._bootstrap>", line 488, in _call_with_frames_removed
  File "/app/crm/urls.py", line 32, in <module>
    path("contacts/", include("contacts.api_urls")),
                      ~~~~~~~^^^^^^^^^^^^^^^^^^^^^
  File "/app/.venv/lib/python3.13/site-packages/django/urls/conf.py", line 39, in include
    urlconf_module = import_module(urlconf_module)
  File "/usr/local/lib/python3.13/importlib/__init__.py", line 88, in import_module
    return _bootstrap._gcd_import(name[level:], package, level)
           ~~~~~~~~~~~~~~~~~~~~~~^^^^^^^^^^^^^^^^^^^^^^^^^^^^^^
  File "<frozen importlib._bootstrap>", line 1387, in _gcd_import
  File "<frozen importlib._bootstrap>", line 1360, in _find_and_load
  File "<frozen importlib._bootstrap>", line 1324, in _find_and_load_unlocked
ModuleNotFoundError: No module named 'contacts.api_urls'

During handling of the above exception, another exception occurred:

Traceback (most recent call last):
  File "/app/.venv/lib/python3.13/site-packages/celery/utils/dispatch/signal.py", line 280, in send
    response = receiver(signal=self, sender=sender, **named)
  File "/app/.venv/lib/python3.13/site-packages/celery/fixups/django.py", line 101, in on_import_modules
    self.worker_fixup.validate_models()
    ~~~~~~~~~~~~~~~~~~~~~~~~~~~~~~~~~^^
  File "/app/.venv/lib/python3.13/site-packages/celery/fixups/django.py", line 141, in validate_models
    run_checks()
    ~~~~~~~~~~^^
  File "/app/.venv/lib/python3.13/site-packages/django/core/checks/registry.py", line 89, in run_checks
    new_errors = check(app_configs=app_configs, databases=databases)
  File "/app/.venv/lib/python3.13/site-packages/django/core/checks/urls.py", line 138, in check_custom_error_handlers
    path = getattr(resolver.urlconf_module, "handler%s" % status_code)
                   ^^^^^^^^^^^^^^^^^^^^^^^
  File "/app/.venv/lib/python3.13/site-packages/django/utils/functional.py", line 47, in __get__
    res = instance.__dict__[self.name] = self.func(instance)
                                         ~~~~~~~~~^^^^^^^^^^
  File "/app/.venv/lib/python3.13/site-packages/django/urls/resolvers.py", line 711, in urlconf_module
    return import_module(self.urlconf_name)
  File "/usr/local/lib/python3.13/importlib/__init__.py", line 88, in import_module
    return _bootstrap._gcd_import(name[level:], package, level)
           ~~~~~~~~~~~~~~~~~~~~~~^^^^^^^^^^^^^^^^^^^^^^^^^^^^^^
  File "<frozen importlib._bootstrap>", line 1387, in _gcd_import
  File "<frozen importlib._bootstrap>", line 1360, in _find_and_load
  File "<frozen importlib._bootstrap>", line 1331, in _find_and_load_unlocked
  File "<frozen importlib._bootstrap>", line 935, in _load_unlocked
  File "<frozen importlib._bootstrap_external>", line 1027, in exec_module
  File "<frozen importlib._bootstrap>", line 488, in _call_with_frames_removed
  File "/app/crm/urls.py", line 32, in <module>
    path("contacts/", include("contacts.api_urls")),
                      ~~~~~~~^^^^^^^^^^^^^^^^^^^^^
  File "/app/.venv/lib/python3.13/site-packages/django/urls/conf.py", line 39, in include
    urlconf_module = import_module(urlconf_module)
  File "/usr/local/lib/python3.13/importlib/__init__.py", line 88, in import_module
    return _bootstrap._gcd_import(name[level:], package, level)
           ~~~~~~~~~~~~~~~~~~~~~~^^^^^^^^^^^^^^^^^^^^^^^^^^^^^^
  File "<frozen importlib._bootstrap>", line 1387, in _gcd_import
  File "<frozen importlib._bootstrap>", line 1360, in _find_and_load
  File "<frozen importlib._bootstrap>", line 1324, in _find_and_load_unlocked
ModuleNotFoundError: No module named 'contacts.api_urls'
INFO 2025-10-29 18:11:54,866 autoreload 10 139882352724928 Watching for file changes with StatReloader
ERROR 2025-10-29 18:11:55,018 signal 9 140020422257600 Signal handler <bound method DjangoFixup.on_import_modules of <celery.fixups.django.DjangoFixup object at 0x7f59099e6660>> raised: ImportError("cannot import name 'check_user_permission' from 'users.permissions' (/app/users/permissions.py)")
Traceback (most recent call last):
  File "/app/.venv/lib/python3.13/site-packages/django/core/checks/urls.py", line 136, in check_custom_error_handlers
    handler = resolver.resolve_error_handler(status_code)
  File "/app/.venv/lib/python3.13/site-packages/django/urls/resolvers.py", line 732, in resolve_error_handler
    callback = getattr(self.urlconf_module, "handler%s" % view_type, None)
                       ^^^^^^^^^^^^^^^^^^^
  File "/app/.venv/lib/python3.13/site-packages/django/utils/functional.py", line 47, in __get__
    res = instance.__dict__[self.name] = self.func(instance)
                                         ~~~~~~~~~^^^^^^^^^^
  File "/app/.venv/lib/python3.13/site-packages/django/urls/resolvers.py", line 711, in urlconf_module
    return import_module(self.urlconf_name)
  File "/usr/local/lib/python3.13/importlib/__init__.py", line 88, in import_module
    return _bootstrap._gcd_import(name[level:], package, level)
           ~~~~~~~~~~~~~~~~~~~~~~^^^^^^^^^^^^^^^^^^^^^^^^^^^^^^
  File "<frozen importlib._bootstrap>", line 1387, in _gcd_import
  File "<frozen importlib._bootstrap>", line 1360, in _find_and_load
  File "<frozen importlib._bootstrap>", line 1331, in _find_and_load_unlocked
  File "<frozen importlib._bootstrap>", line 935, in _load_unlocked
  File "<frozen importlib._bootstrap_external>", line 1027, in exec_module
  File "<frozen importlib._bootstrap>", line 488, in _call_with_frames_removed
  File "/app/crm/urls.py", line 41, in <module>
    path("contacts/", include("contacts.urls")),
                      ~~~~~~~^^^^^^^^^^^^^^^^^
  File "/app/.venv/lib/python3.13/site-packages/django/urls/conf.py", line 39, in include
    urlconf_module = import_module(urlconf_module)
  File "/usr/local/lib/python3.13/importlib/__init__.py", line 88, in import_module
    return _bootstrap._gcd_import(name[level:], package, level)
           ~~~~~~~~~~~~~~~~~~~~~~^^^^^^^^^^^^^^^^^^^^^^^^^^^^^^
  File "<frozen importlib._bootstrap>", line 1387, in _gcd_import
  File "<frozen importlib._bootstrap>", line 1360, in _find_and_load
  File "<frozen importlib._bootstrap>", line 1331, in _find_and_load_unlocked
  File "<frozen importlib._bootstrap>", line 935, in _load_unlocked
  File "<frozen importlib._bootstrap_external>", line 1027, in exec_module
  File "<frozen importlib._bootstrap>", line 488, in _call_with_frames_removed
  File "/app/contacts/urls.py", line 2, in <module>
    from . import views
  File "/app/contacts/views.py", line 26, in <module>
    from users.permissions import RBACPermission, check_user_permission
ImportError: cannot import name 'check_user_permission' from 'users.permissions' (/app/users/permissions.py)

During handling of the above exception, another exception occurred:

Traceback (most recent call last):
  File "/app/.venv/lib/python3.13/site-packages/celery/utils/dispatch/signal.py", line 280, in send
    response = receiver(signal=self, sender=sender, **named)
  File "/app/.venv/lib/python3.13/site-packages/celery/fixups/django.py", line 101, in on_import_modules
    self.worker_fixup.validate_models()
    ~~~~~~~~~~~~~~~~~~~~~~~~~~~~~~~~~^^
  File "/app/.venv/lib/python3.13/site-packages/celery/fixups/django.py", line 141, in validate_models
    run_checks()
    ~~~~~~~~~~^^
  File "/app/.venv/lib/python3.13/site-packages/django/core/checks/registry.py", line 89, in run_checks
    new_errors = check(app_configs=app_configs, databases=databases)
  File "/app/.venv/lib/python3.13/site-packages/django/core/checks/urls.py", line 138, in check_custom_error_handlers
    path = getattr(resolver.urlconf_module, "handler%s" % status_code)
                   ^^^^^^^^^^^^^^^^^^^^^^^
  File "/app/.venv/lib/python3.13/site-packages/django/utils/functional.py", line 47, in __get__
    res = instance.__dict__[self.name] = self.func(instance)
                                         ~~~~~~~~~^^^^^^^^^^
  File "/app/.venv/lib/python3.13/site-packages/django/urls/resolvers.py", line 711, in urlconf_module
    return import_module(self.urlconf_name)
  File "/usr/local/lib/python3.13/importlib/__init__.py", line 88, in import_module
    return _bootstrap._gcd_import(name[level:], package, level)
           ~~~~~~~~~~~~~~~~~~~~~~^^^^^^^^^^^^^^^^^^^^^^^^^^^^^^
  File "<frozen importlib._bootstrap>", line 1387, in _gcd_import
  File "<frozen importlib._bootstrap>", line 1360, in _find_and_load
  File "<frozen importlib._bootstrap>", line 1331, in _find_and_load_unlocked
  File "<frozen importlib._bootstrap>", line 935, in _load_unlocked
  File "<frozen importlib._bootstrap_external>", line 1027, in exec_module
  File "<frozen importlib._bootstrap>", line 488, in _call_with_frames_removed
  File "/app/crm/urls.py", line 41, in <module>
    path("contacts/", include("contacts.urls")),
                      ~~~~~~~^^^^^^^^^^^^^^^^^
  File "/app/.venv/lib/python3.13/site-packages/django/urls/conf.py", line 39, in include
    urlconf_module = import_module(urlconf_module)
  File "/usr/local/lib/python3.13/importlib/__init__.py", line 88, in import_module
    return _bootstrap._gcd_import(name[level:], package, level)
           ~~~~~~~~~~~~~~~~~~~~~~^^^^^^^^^^^^^^^^^^^^^^^^^^^^^^
  File "<frozen importlib._bootstrap>", line 1387, in _gcd_import
  File "<frozen importlib._bootstrap>", line 1360, in _find_and_load
  File "<frozen importlib._bootstrap>", line 1331, in _find_and_load_unlocked
  File "<frozen importlib._bootstrap>", line 935, in _load_unlocked
  File "<frozen importlib._bootstrap_external>", line 1027, in exec_module
  File "<frozen importlib._bootstrap>", line 488, in _call_with_frames_removed
  File "/app/contacts/urls.py", line 2, in <module>
    from . import views
  File "/app/contacts/views.py", line 26, in <module>
    from users.permissions import RBACPermission, check_user_permission
ImportError: cannot import name 'check_user_permission' from 'users.permissions' (/app/users/permissions.py)
ERROR 2025-10-29 18:11:55,844 signal 10 140180309490624 Signal handler <bound method DjangoFixup.on_import_modules of <celery.fixups.django.DjangoFixup object at 0x7f7e43a2e660>> raised: ImportError("cannot import name 'check_user_permission' from 'users.permissions' (/app/users/permissions.py)")
Traceback (most recent call last):
  File "/app/.venv/lib/python3.13/site-packages/django/core/checks/urls.py", line 136, in check_custom_error_handlers
    handler = resolver.resolve_error_handler(status_code)
  File "/app/.venv/lib/python3.13/site-packages/django/urls/resolvers.py", line 732, in resolve_error_handler
    callback = getattr(self.urlconf_module, "handler%s" % view_type, None)
                       ^^^^^^^^^^^^^^^^^^^
  File "/app/.venv/lib/python3.13/site-packages/django/utils/functional.py", line 47, in __get__
    res = instance.__dict__[self.name] = self.func(instance)
                                         ~~~~~~~~~^^^^^^^^^^
  File "/app/.venv/lib/python3.13/site-packages/django/urls/resolvers.py", line 711, in urlconf_module
    return import_module(self.urlconf_name)
  File "/usr/local/lib/python3.13/importlib/__init__.py", line 88, in import_module
    return _bootstrap._gcd_import(name[level:], package, level)
           ~~~~~~~~~~~~~~~~~~~~~~^^^^^^^^^^^^^^^^^^^^^^^^^^^^^^
  File "<frozen importlib._bootstrap>", line 1387, in _gcd_import
  File "<frozen importlib._bootstrap>", line 1360, in _find_and_load
  File "<frozen importlib._bootstrap>", line 1331, in _find_and_load_unlocked
  File "<frozen importlib._bootstrap>", line 935, in _load_unlocked
  File "<frozen importlib._bootstrap_external>", line 1027, in exec_module
  File "<frozen importlib._bootstrap>", line 488, in _call_with_frames_removed
  File "/app/crm/urls.py", line 41, in <module>
    path("contacts/", include("contacts.urls")),
                      ~~~~~~~^^^^^^^^^^^^^^^^^
  File "/app/.venv/lib/python3.13/site-packages/django/urls/conf.py", line 39, in include
    urlconf_module = import_module(urlconf_module)
  File "/usr/local/lib/python3.13/importlib/__init__.py", line 88, in import_module
    return _bootstrap._gcd_import(name[level:], package, level)
           ~~~~~~~~~~~~~~~~~~~~~~^^^^^^^^^^^^^^^^^^^^^^^^^^^^^^
  File "<frozen importlib._bootstrap>", line 1387, in _gcd_import
  File "<frozen importlib._bootstrap>", line 1360, in _find_and_load
  File "<frozen importlib._bootstrap>", line 1331, in _find_and_load_unlocked
  File "<frozen importlib._bootstrap>", line 935, in _load_unlocked
  File "<frozen importlib._bootstrap_external>", line 1027, in exec_module
  File "<frozen importlib._bootstrap>", line 488, in _call_with_frames_removed
  File "/app/contacts/urls.py", line 2, in <module>
    from . import views
  File "/app/contacts/views.py", line 26, in <module>
    from users.permissions import RBACPermission, check_user_permission
ImportError: cannot import name 'check_user_permission' from 'users.permissions' (/app/users/permissions.py)

During handling of the above exception, another exception occurred:

Traceback (most recent call last):
  File "/app/.venv/lib/python3.13/site-packages/celery/utils/dispatch/signal.py", line 280, in send
    response = receiver(signal=self, sender=sender, **named)
  File "/app/.venv/lib/python3.13/site-packages/celery/fixups/django.py", line 101, in on_import_modules
    self.worker_fixup.validate_models()
    ~~~~~~~~~~~~~~~~~~~~~~~~~~~~~~~~~^^
  File "/app/.venv/lib/python3.13/site-packages/celery/fixups/django.py", line 141, in validate_models
    run_checks()
    ~~~~~~~~~~^^
  File "/app/.venv/lib/python3.13/site-packages/django/core/checks/registry.py", line 89, in run_checks
    new_errors = check(app_configs=app_configs, databases=databases)
  File "/app/.venv/lib/python3.13/site-packages/django/core/checks/urls.py", line 138, in check_custom_error_handlers
    path = getattr(resolver.urlconf_module, "handler%s" % status_code)
                   ^^^^^^^^^^^^^^^^^^^^^^^
  File "/app/.venv/lib/python3.13/site-packages/django/utils/functional.py", line 47, in __get__
    res = instance.__dict__[self.name] = self.func(instance)
                                         ~~~~~~~~~^^^^^^^^^^
  File "/app/.venv/lib/python3.13/site-packages/django/urls/resolvers.py", line 711, in urlconf_module
    return import_module(self.urlconf_name)
  File "/usr/local/lib/python3.13/importlib/__init__.py", line 88, in import_module
    return _bootstrap._gcd_import(name[level:], package, level)
           ~~~~~~~~~~~~~~~~~~~~~~^^^^^^^^^^^^^^^^^^^^^^^^^^^^^^
  File "<frozen importlib._bootstrap>", line 1387, in _gcd_import
  File "<frozen importlib._bootstrap>", line 1360, in _find_and_load
  File "<frozen importlib._bootstrap>", line 1331, in _find_and_load_unlocked
  File "<frozen importlib._bootstrap>", line 935, in _load_unlocked
  File "<frozen importlib._bootstrap_external>", line 1027, in exec_module
  File "<frozen importlib._bootstrap>", line 488, in _call_with_frames_removed
  File "/app/crm/urls.py", line 41, in <module>
    path("contacts/", include("contacts.urls")),
                      ~~~~~~~^^^^^^^^^^^^^^^^^
  File "/app/.venv/lib/python3.13/site-packages/django/urls/conf.py", line 39, in include
    urlconf_module = import_module(urlconf_module)
  File "/usr/local/lib/python3.13/importlib/__init__.py", line 88, in import_module
    return _bootstrap._gcd_import(name[level:], package, level)
           ~~~~~~~~~~~~~~~~~~~~~~^^^^^^^^^^^^^^^^^^^^^^^^^^^^^^
  File "<frozen importlib._bootstrap>", line 1387, in _gcd_import
  File "<frozen importlib._bootstrap>", line 1360, in _find_and_load
  File "<frozen importlib._bootstrap>", line 1331, in _find_and_load_unlocked
  File "<frozen importlib._bootstrap>", line 935, in _load_unlocked
  File "<frozen importlib._bootstrap_external>", line 1027, in exec_module
  File "<frozen importlib._bootstrap>", line 488, in _call_with_frames_removed
  File "/app/contacts/urls.py", line 2, in <module>
    from . import views
  File "/app/contacts/views.py", line 26, in <module>
    from users.permissions import RBACPermission, check_user_permission
ImportError: cannot import name 'check_user_permission' from 'users.permissions' (/app/users/permissions.py)
INFO 2025-10-29 18:14:33,258 autoreload 10 139882352724928 /app/contacts/views.py changed, reloading.
INFO 2025-10-29 18:14:39,482 autoreload 14 139696671914944 Watching for file changes with StatReloader
ERROR 2025-10-29 18:29:58,069 signal 35 139934422875072 Signal handler <bound method DjangoFixup.on_import_modules of <celery.fixups.django.DjangoFixup object at 0x7f4503a6b4d0>> raised: ImportError("cannot import name 'check_user_permission' from 'users.permissions' (/app/users/permissions.py)")
Traceback (most recent call last):
  File "/app/.venv/lib/python3.13/site-packages/django/core/checks/urls.py", line 136, in check_custom_error_handlers
    handler = resolver.resolve_error_handler(status_code)
  File "/app/.venv/lib/python3.13/site-packages/django/urls/resolvers.py", line 732, in resolve_error_handler
    callback = getattr(self.urlconf_module, "handler%s" % view_type, None)
                       ^^^^^^^^^^^^^^^^^^^
  File "/app/.venv/lib/python3.13/site-packages/django/utils/functional.py", line 47, in __get__
    res = instance.__dict__[self.name] = self.func(instance)
                                         ~~~~~~~~~^^^^^^^^^^
  File "/app/.venv/lib/python3.13/site-packages/django/urls/resolvers.py", line 711, in urlconf_module
    return import_module(self.urlconf_name)
  File "/usr/local/lib/python3.13/importlib/__init__.py", line 88, in import_module
    return _bootstrap._gcd_import(name[level:], package, level)
           ~~~~~~~~~~~~~~~~~~~~~~^^^^^^^^^^^^^^^^^^^^^^^^^^^^^^
  File "<frozen importlib._bootstrap>", line 1387, in _gcd_import
  File "<frozen importlib._bootstrap>", line 1360, in _find_and_load
  File "<frozen importlib._bootstrap>", line 1331, in _find_and_load_unlocked
  File "<frozen importlib._bootstrap>", line 935, in _load_unlocked
  File "<frozen importlib._bootstrap_external>", line 1027, in exec_module
  File "<frozen importlib._bootstrap>", line 488, in _call_with_frames_removed
  File "/app/crm/urls.py", line 41, in <module>
    path("contacts/", include("contacts.urls")),
                      ~~~~~~~^^^^^^^^^^^^^^^^^
  File "/app/.venv/lib/python3.13/site-packages/django/urls/conf.py", line 39, in include
    urlconf_module = import_module(urlconf_module)
  File "/usr/local/lib/python3.13/importlib/__init__.py", line 88, in import_module
    return _bootstrap._gcd_import(name[level:], package, level)
           ~~~~~~~~~~~~~~~~~~~~~~^^^^^^^^^^^^^^^^^^^^^^^^^^^^^^
  File "<frozen importlib._bootstrap>", line 1387, in _gcd_import
  File "<frozen importlib._bootstrap>", line 1360, in _find_and_load
  File "<frozen importlib._bootstrap>", line 1331, in _find_and_load_unlocked
  File "<frozen importlib._bootstrap>", line 935, in _load_unlocked
  File "<frozen importlib._bootstrap_external>", line 1027, in exec_module
  File "<frozen importlib._bootstrap>", line 488, in _call_with_frames_removed
  File "/app/contacts/urls.py", line 2, in <module>
    from . import views
  File "/app/contacts/views.py", line 26, in <module>
    from users.permissions import (RBACPermission, check_user_permission,)
ImportError: cannot import name 'check_user_permission' from 'users.permissions' (/app/users/permissions.py)

During handling of the above exception, another exception occurred:

Traceback (most recent call last):
  File "/app/.venv/lib/python3.13/site-packages/celery/utils/dispatch/signal.py", line 280, in send
    response = receiver(signal=self, sender=sender, **named)
  File "/app/.venv/lib/python3.13/site-packages/celery/fixups/django.py", line 101, in on_import_modules
    self.worker_fixup.validate_models()
    ~~~~~~~~~~~~~~~~~~~~~~~~~~~~~~~~~^^
  File "/app/.venv/lib/python3.13/site-packages/celery/fixups/django.py", line 141, in validate_models
    run_checks()
    ~~~~~~~~~~^^
  File "/app/.venv/lib/python3.13/site-packages/django/core/checks/registry.py", line 89, in run_checks
    new_errors = check(app_configs=app_configs, databases=databases)
  File "/app/.venv/lib/python3.13/site-packages/django/core/checks/urls.py", line 138, in check_custom_error_handlers
    path = getattr(resolver.urlconf_module, "handler%s" % status_code)
                   ^^^^^^^^^^^^^^^^^^^^^^^
  File "/app/.venv/lib/python3.13/site-packages/django/utils/functional.py", line 47, in __get__
    res = instance.__dict__[self.name] = self.func(instance)
                                         ~~~~~~~~~^^^^^^^^^^
  File "/app/.venv/lib/python3.13/site-packages/django/urls/resolvers.py", line 711, in urlconf_module
    return import_module(self.urlconf_name)
  File "/usr/local/lib/python3.13/importlib/__init__.py", line 88, in import_module
    return _bootstrap._gcd_import(name[level:], package, level)
           ~~~~~~~~~~~~~~~~~~~~~~^^^^^^^^^^^^^^^^^^^^^^^^^^^^^^
  File "<frozen importlib._bootstrap>", line 1387, in _gcd_import
  File "<frozen importlib._bootstrap>", line 1360, in _find_and_load
  File "<frozen importlib._bootstrap>", line 1331, in _find_and_load_unlocked
  File "<frozen importlib._bootstrap>", line 935, in _load_unlocked
  File "<frozen importlib._bootstrap_external>", line 1027, in exec_module
  File "<frozen importlib._bootstrap>", line 488, in _call_with_frames_removed
  File "/app/crm/urls.py", line 41, in <module>
    path("contacts/", include("contacts.urls")),
                      ~~~~~~~^^^^^^^^^^^^^^^^^
  File "/app/.venv/lib/python3.13/site-packages/django/urls/conf.py", line 39, in include
    urlconf_module = import_module(urlconf_module)
  File "/usr/local/lib/python3.13/importlib/__init__.py", line 88, in import_module
    return _bootstrap._gcd_import(name[level:], package, level)
           ~~~~~~~~~~~~~~~~~~~~~~^^^^^^^^^^^^^^^^^^^^^^^^^^^^^^
  File "<frozen importlib._bootstrap>", line 1387, in _gcd_import
  File "<frozen importlib._bootstrap>", line 1360, in _find_and_load
  File "<frozen importlib._bootstrap>", line 1331, in _find_and_load_unlocked
  File "<frozen importlib._bootstrap>", line 935, in _load_unlocked
  File "<frozen importlib._bootstrap_external>", line 1027, in exec_module
  File "<frozen importlib._bootstrap>", line 488, in _call_with_frames_removed
  File "/app/contacts/urls.py", line 2, in <module>
    from . import views
  File "/app/contacts/views.py", line 26, in <module>
    from users.permissions import (RBACPermission, check_user_permission,)
ImportError: cannot import name 'check_user_permission' from 'users.permissions' (/app/users/permissions.py)
ERROR 2025-10-29 18:31:05,156 signal 9 139968220064704 Signal handler <bound method DjangoFixup.on_import_modules of <celery.fixups.django.DjangoFixup object at 0x7f4ce2202660>> raised: ImportError("cannot import name 'check_user_permission' from 'users.permissions' (/app/users/permissions.py)")
Traceback (most recent call last):
  File "/app/.venv/lib/python3.13/site-packages/django/core/checks/urls.py", line 136, in check_custom_error_handlers
    handler = resolver.resolve_error_handler(status_code)
  File "/app/.venv/lib/python3.13/site-packages/django/urls/resolvers.py", line 732, in resolve_error_handler
    callback = getattr(self.urlconf_module, "handler%s" % view_type, None)
                       ^^^^^^^^^^^^^^^^^^^
  File "/app/.venv/lib/python3.13/site-packages/django/utils/functional.py", line 47, in __get__
    res = instance.__dict__[self.name] = self.func(instance)
                                         ~~~~~~~~~^^^^^^^^^^
  File "/app/.venv/lib/python3.13/site-packages/django/urls/resolvers.py", line 711, in urlconf_module
    return import_module(self.urlconf_name)
  File "/usr/local/lib/python3.13/importlib/__init__.py", line 88, in import_module
    return _bootstrap._gcd_import(name[level:], package, level)
           ~~~~~~~~~~~~~~~~~~~~~~^^^^^^^^^^^^^^^^^^^^^^^^^^^^^^
  File "<frozen importlib._bootstrap>", line 1387, in _gcd_import
  File "<frozen importlib._bootstrap>", line 1360, in _find_and_load
  File "<frozen importlib._bootstrap>", line 1331, in _find_and_load_unlocked
  File "<frozen importlib._bootstrap>", line 935, in _load_unlocked
  File "<frozen importlib._bootstrap_external>", line 1027, in exec_module
  File "<frozen importlib._bootstrap>", line 488, in _call_with_frames_removed
  File "/app/crm/urls.py", line 41, in <module>
    path("contacts/", include("contacts.urls")),
                      ~~~~~~~^^^^^^^^^^^^^^^^^
  File "/app/.venv/lib/python3.13/site-packages/django/urls/conf.py", line 39, in include
    urlconf_module = import_module(urlconf_module)
  File "/usr/local/lib/python3.13/importlib/__init__.py", line 88, in import_module
    return _bootstrap._gcd_import(name[level:], package, level)
           ~~~~~~~~~~~~~~~~~~~~~~^^^^^^^^^^^^^^^^^^^^^^^^^^^^^^
  File "<frozen importlib._bootstrap>", line 1387, in _gcd_import
  File "<frozen importlib._bootstrap>", line 1360, in _find_and_load
  File "<frozen importlib._bootstrap>", line 1331, in _find_and_load_unlocked
  File "<frozen importlib._bootstrap>", line 935, in _load_unlocked
  File "<frozen importlib._bootstrap_external>", line 1027, in exec_module
  File "<frozen importlib._bootstrap>", line 488, in _call_with_frames_removed
  File "/app/contacts/urls.py", line 2, in <module>
    from . import views
  File "/app/contacts/views.py", line 26, in <module>
    from users.permissions import (RBACPermission, check_user_permission,)
ImportError: cannot import name 'check_user_permission' from 'users.permissions' (/app/users/permissions.py)

During handling of the above exception, another exception occurred:

Traceback (most recent call last):
  File "/app/.venv/lib/python3.13/site-packages/celery/utils/dispatch/signal.py", line 280, in send
    response = receiver(signal=self, sender=sender, **named)
  File "/app/.venv/lib/python3.13/site-packages/celery/fixups/django.py", line 101, in on_import_modules
    self.worker_fixup.validate_models()
    ~~~~~~~~~~~~~~~~~~~~~~~~~~~~~~~~~^^
  File "/app/.venv/lib/python3.13/site-packages/celery/fixups/django.py", line 141, in validate_models
    run_checks()
    ~~~~~~~~~~^^
  File "/app/.venv/lib/python3.13/site-packages/django/core/checks/registry.py", line 89, in run_checks
    new_errors = check(app_configs=app_configs, databases=databases)
  File "/app/.venv/lib/python3.13/site-packages/django/core/checks/urls.py", line 138, in check_custom_error_handlers
    path = getattr(resolver.urlconf_module, "handler%s" % status_code)
                   ^^^^^^^^^^^^^^^^^^^^^^^
  File "/app/.venv/lib/python3.13/site-packages/django/utils/functional.py", line 47, in __get__
    res = instance.__dict__[self.name] = self.func(instance)
                                         ~~~~~~~~~^^^^^^^^^^
  File "/app/.venv/lib/python3.13/site-packages/django/urls/resolvers.py", line 711, in urlconf_module
    return import_module(self.urlconf_name)
  File "/usr/local/lib/python3.13/importlib/__init__.py", line 88, in import_module
    return _bootstrap._gcd_import(name[level:], package, level)
           ~~~~~~~~~~~~~~~~~~~~~~^^^^^^^^^^^^^^^^^^^^^^^^^^^^^^
  File "<frozen importlib._bootstrap>", line 1387, in _gcd_import
  File "<frozen importlib._bootstrap>", line 1360, in _find_and_load
  File "<frozen importlib._bootstrap>", line 1331, in _find_and_load_unlocked
  File "<frozen importlib._bootstrap>", line 935, in _load_unlocked
  File "<frozen importlib._bootstrap_external>", line 1027, in exec_module
  File "<frozen importlib._bootstrap>", line 488, in _call_with_frames_removed
  File "/app/crm/urls.py", line 41, in <module>
    path("contacts/", include("contacts.urls")),
                      ~~~~~~~^^^^^^^^^^^^^^^^^
  File "/app/.venv/lib/python3.13/site-packages/django/urls/conf.py", line 39, in include
    urlconf_module = import_module(urlconf_module)
  File "/usr/local/lib/python3.13/importlib/__init__.py", line 88, in import_module
    return _bootstrap._gcd_import(name[level:], package, level)
           ~~~~~~~~~~~~~~~~~~~~~~^^^^^^^^^^^^^^^^^^^^^^^^^^^^^^
  File "<frozen importlib._bootstrap>", line 1387, in _gcd_import
  File "<frozen importlib._bootstrap>", line 1360, in _find_and_load
  File "<frozen importlib._bootstrap>", line 1331, in _find_and_load_unlocked
  File "<frozen importlib._bootstrap>", line 935, in _load_unlocked
  File "<frozen importlib._bootstrap_external>", line 1027, in exec_module
  File "<frozen importlib._bootstrap>", line 488, in _call_with_frames_removed
  File "/app/contacts/urls.py", line 2, in <module>
    from . import views
  File "/app/contacts/views.py", line 26, in <module>
    from users.permissions import (RBACPermission, check_user_permission,)
ImportError: cannot import name 'check_user_permission' from 'users.permissions' (/app/users/permissions.py)
ERROR 2025-10-29 18:31:18,739 signal 81 139639130975168 Signal handler <bound method DjangoFixup.on_import_modules of <celery.fixups.django.DjangoFixup object at 0x7f0042ad6a50>> raised: ImportError("cannot import name 'check_user_permission' from 'users.permissions' (/app/users/permissions.py)")
Traceback (most recent call last):
  File "/app/.venv/lib/python3.13/site-packages/celery/utils/dispatch/signal.py", line 280, in send
    response = receiver(signal=self, sender=sender, **named)
  File "/app/.venv/lib/python3.13/site-packages/celery/fixups/django.py", line 101, in on_import_modules
    self.worker_fixup.validate_models()
    ~~~~~~~~~~~~~~~~~~~~~~~~~~~~~~~~~^^
  File "/app/.venv/lib/python3.13/site-packages/celery/fixups/django.py", line 141, in validate_models
    run_checks()
    ~~~~~~~~~~^^
  File "/app/.venv/lib/python3.13/site-packages/django/core/checks/registry.py", line 89, in run_checks
    new_errors = check(app_configs=app_configs, databases=databases)
  File "/app/.venv/lib/python3.13/site-packages/django/core/checks/urls.py", line 44, in check_url_namespaces_unique
    all_namespaces = _load_all_namespaces(resolver)
  File "/app/.venv/lib/python3.13/site-packages/django/core/checks/urls.py", line 63, in _load_all_namespaces
    url_patterns = getattr(resolver, "url_patterns", [])
  File "/app/.venv/lib/python3.13/site-packages/django/utils/functional.py", line 47, in __get__
    res = instance.__dict__[self.name] = self.func(instance)
                                         ~~~~~~~~~^^^^^^^^^^
  File "/app/.venv/lib/python3.13/site-packages/django/urls/resolvers.py", line 718, in url_patterns
    patterns = getattr(self.urlconf_module, "urlpatterns", self.urlconf_module)
                       ^^^^^^^^^^^^^^^^^^^
  File "/app/.venv/lib/python3.13/site-packages/django/utils/functional.py", line 47, in __get__
    res = instance.__dict__[self.name] = self.func(instance)
                                         ~~~~~~~~~^^^^^^^^^^
  File "/app/.venv/lib/python3.13/site-packages/django/urls/resolvers.py", line 711, in urlconf_module
    return import_module(self.urlconf_name)
  File "/usr/local/lib/python3.13/importlib/__init__.py", line 88, in import_module
    return _bootstrap._gcd_import(name[level:], package, level)
           ~~~~~~~~~~~~~~~~~~~~~~^^^^^^^^^^^^^^^^^^^^^^^^^^^^^^
  File "<frozen importlib._bootstrap>", line 1387, in _gcd_import
  File "<frozen importlib._bootstrap>", line 1360, in _find_and_load
  File "<frozen importlib._bootstrap>", line 1331, in _find_and_load_unlocked
  File "<frozen importlib._bootstrap>", line 935, in _load_unlocked
  File "<frozen importlib._bootstrap_external>", line 1027, in exec_module
  File "<frozen importlib._bootstrap>", line 488, in _call_with_frames_removed
  File "/app/crm/urls.py", line 41, in <module>
    path("contacts/", include("contacts.urls")),
                      ~~~~~~~^^^^^^^^^^^^^^^^^
  File "/app/.venv/lib/python3.13/site-packages/django/urls/conf.py", line 39, in include
    urlconf_module = import_module(urlconf_module)
  File "/usr/local/lib/python3.13/importlib/__init__.py", line 88, in import_module
    return _bootstrap._gcd_import(name[level:], package, level)
           ~~~~~~~~~~~~~~~~~~~~~~^^^^^^^^^^^^^^^^^^^^^^^^^^^^^^
  File "<frozen importlib._bootstrap>", line 1387, in _gcd_import
  File "<frozen importlib._bootstrap>", line 1360, in _find_and_load
  File "<frozen importlib._bootstrap>", line 1331, in _find_and_load_unlocked
  File "<frozen importlib._bootstrap>", line 935, in _load_unlocked
  File "<frozen importlib._bootstrap_external>", line 1027, in exec_module
  File "<frozen importlib._bootstrap>", line 488, in _call_with_frames_removed
  File "/app/contacts/urls.py", line 2, in <module>
    from . import views
  File "/app/contacts/views.py", line 26, in <module>
    from users.permissions import (RBACPermission, check_user_permission,)
ImportError: cannot import name 'check_user_permission' from 'users.permissions' (/app/users/permissions.py)
INFO 2025-10-29 18:31:20,115 autoreload 94 140316301450176 Watching for file changes with StatReloader
ERROR 2025-10-29 18:39:13,998 signal 10 140499011107776 Signal handler <bound method DjangoFixup.on_import_modules of <celery.fixups.django.DjangoFixup object at 0x7fc877bba660>> raised: ImportError("cannot import name 'check_user_permission' from 'users.permissions' (/app/users/permissions.py)")
Traceback (most recent call last):
  File "/app/.venv/lib/python3.13/site-packages/django/core/checks/urls.py", line 136, in check_custom_error_handlers
    handler = resolver.resolve_error_handler(status_code)
  File "/app/.venv/lib/python3.13/site-packages/django/urls/resolvers.py", line 732, in resolve_error_handler
    callback = getattr(self.urlconf_module, "handler%s" % view_type, None)
                       ^^^^^^^^^^^^^^^^^^^
  File "/app/.venv/lib/python3.13/site-packages/django/utils/functional.py", line 47, in __get__
    res = instance.__dict__[self.name] = self.func(instance)
                                         ~~~~~~~~~^^^^^^^^^^
  File "/app/.venv/lib/python3.13/site-packages/django/urls/resolvers.py", line 711, in urlconf_module
    return import_module(self.urlconf_name)
  File "/usr/local/lib/python3.13/importlib/__init__.py", line 88, in import_module
    return _bootstrap._gcd_import(name[level:], package, level)
           ~~~~~~~~~~~~~~~~~~~~~~^^^^^^^^^^^^^^^^^^^^^^^^^^^^^^
  File "<frozen importlib._bootstrap>", line 1387, in _gcd_import
  File "<frozen importlib._bootstrap>", line 1360, in _find_and_load
  File "<frozen importlib._bootstrap>", line 1331, in _find_and_load_unlocked
  File "<frozen importlib._bootstrap>", line 935, in _load_unlocked
  File "<frozen importlib._bootstrap_external>", line 1027, in exec_module
  File "<frozen importlib._bootstrap>", line 488, in _call_with_frames_removed
  File "/app/crm/urls.py", line 41, in <module>
    path("contacts/", include("contacts.urls")),
                      ~~~~~~~^^^^^^^^^^^^^^^^^
  File "/app/.venv/lib/python3.13/site-packages/django/urls/conf.py", line 39, in include
    urlconf_module = import_module(urlconf_module)
  File "/usr/local/lib/python3.13/importlib/__init__.py", line 88, in import_module
    return _bootstrap._gcd_import(name[level:], package, level)
           ~~~~~~~~~~~~~~~~~~~~~~^^^^^^^^^^^^^^^^^^^^^^^^^^^^^^
  File "<frozen importlib._bootstrap>", line 1387, in _gcd_import
  File "<frozen importlib._bootstrap>", line 1360, in _find_and_load
  File "<frozen importlib._bootstrap>", line 1331, in _find_and_load_unlocked
  File "<frozen importlib._bootstrap>", line 935, in _load_unlocked
  File "<frozen importlib._bootstrap_external>", line 1027, in exec_module
  File "<frozen importlib._bootstrap>", line 488, in _call_with_frames_removed
  File "/app/contacts/urls.py", line 2, in <module>
    from . import views
  File "/app/contacts/views.py", line 26, in <module>
    from users.permissions import (RBACPermission, check_user_permission,)
ImportError: cannot import name 'check_user_permission' from 'users.permissions' (/app/users/permissions.py)

During handling of the above exception, another exception occurred:

Traceback (most recent call last):
  File "/app/.venv/lib/python3.13/site-packages/celery/utils/dispatch/signal.py", line 280, in send
    response = receiver(signal=self, sender=sender, **named)
  File "/app/.venv/lib/python3.13/site-packages/celery/fixups/django.py", line 101, in on_import_modules
    self.worker_fixup.validate_models()
    ~~~~~~~~~~~~~~~~~~~~~~~~~~~~~~~~~^^
  File "/app/.venv/lib/python3.13/site-packages/celery/fixups/django.py", line 141, in validate_models
    run_checks()
    ~~~~~~~~~~^^
  File "/app/.venv/lib/python3.13/site-packages/django/core/checks/registry.py", line 89, in run_checks
    new_errors = check(app_configs=app_configs, databases=databases)
  File "/app/.venv/lib/python3.13/site-packages/django/core/checks/urls.py", line 138, in check_custom_error_handlers
    path = getattr(resolver.urlconf_module, "handler%s" % status_code)
                   ^^^^^^^^^^^^^^^^^^^^^^^
  File "/app/.venv/lib/python3.13/site-packages/django/utils/functional.py", line 47, in __get__
    res = instance.__dict__[self.name] = self.func(instance)
                                         ~~~~~~~~~^^^^^^^^^^
  File "/app/.venv/lib/python3.13/site-packages/django/urls/resolvers.py", line 711, in urlconf_module
    return import_module(self.urlconf_name)
  File "/usr/local/lib/python3.13/importlib/__init__.py", line 88, in import_module
    return _bootstrap._gcd_import(name[level:], package, level)
           ~~~~~~~~~~~~~~~~~~~~~~^^^^^^^^^^^^^^^^^^^^^^^^^^^^^^
  File "<frozen importlib._bootstrap>", line 1387, in _gcd_import
  File "<frozen importlib._bootstrap>", line 1360, in _find_and_load
  File "<frozen importlib._bootstrap>", line 1331, in _find_and_load_unlocked
  File "<frozen importlib._bootstrap>", line 935, in _load_unlocked
  File "<frozen importlib._bootstrap_external>", line 1027, in exec_module
  File "<frozen importlib._bootstrap>", line 488, in _call_with_frames_removed
  File "/app/crm/urls.py", line 41, in <module>
    path("contacts/", include("contacts.urls")),
                      ~~~~~~~^^^^^^^^^^^^^^^^^
  File "/app/.venv/lib/python3.13/site-packages/django/urls/conf.py", line 39, in include
    urlconf_module = import_module(urlconf_module)
  File "/usr/local/lib/python3.13/importlib/__init__.py", line 88, in import_module
    return _bootstrap._gcd_import(name[level:], package, level)
           ~~~~~~~~~~~~~~~~~~~~~~^^^^^^^^^^^^^^^^^^^^^^^^^^^^^^
  File "<frozen importlib._bootstrap>", line 1387, in _gcd_import
  File "<frozen importlib._bootstrap>", line 1360, in _find_and_load
  File "<frozen importlib._bootstrap>", line 1331, in _find_and_load_unlocked
  File "<frozen importlib._bootstrap>", line 935, in _load_unlocked
  File "<frozen importlib._bootstrap_external>", line 1027, in exec_module
  File "<frozen importlib._bootstrap>", line 488, in _call_with_frames_removed
  File "/app/contacts/urls.py", line 2, in <module>
    from . import views
  File "/app/contacts/views.py", line 26, in <module>
    from users.permissions import (RBACPermission, check_user_permission,)
ImportError: cannot import name 'check_user_permission' from 'users.permissions' (/app/users/permissions.py)
INFO 2025-10-29 18:40:50,443 autoreload 94 140316301450176 /app/contacts/views.py changed, reloading.
ERROR 2025-10-29 18:41:22,683 signal 9 140024564984768 Signal handler <bound method DjangoFixup.on_import_modules of <celery.fixups.django.DjangoFixup object at 0x7f5a008b6660>> raised: ImportError("cannot import name 'check_user_permission' from 'users.permissions' (/app/users/permissions.py)")
Traceback (most recent call last):
  File "/app/.venv/lib/python3.13/site-packages/django/core/checks/urls.py", line 136, in check_custom_error_handlers
    handler = resolver.resolve_error_handler(status_code)
  File "/app/.venv/lib/python3.13/site-packages/django/urls/resolvers.py", line 732, in resolve_error_handler
    callback = getattr(self.urlconf_module, "handler%s" % view_type, None)
                       ^^^^^^^^^^^^^^^^^^^
  File "/app/.venv/lib/python3.13/site-packages/django/utils/functional.py", line 47, in __get__
    res = instance.__dict__[self.name] = self.func(instance)
                                         ~~~~~~~~~^^^^^^^^^^
  File "/app/.venv/lib/python3.13/site-packages/django/urls/resolvers.py", line 711, in urlconf_module
    return import_module(self.urlconf_name)
  File "/usr/local/lib/python3.13/importlib/__init__.py", line 88, in import_module
    return _bootstrap._gcd_import(name[level:], package, level)
           ~~~~~~~~~~~~~~~~~~~~~~^^^^^^^^^^^^^^^^^^^^^^^^^^^^^^
  File "<frozen importlib._bootstrap>", line 1387, in _gcd_import
  File "<frozen importlib._bootstrap>", line 1360, in _find_and_load
  File "<frozen importlib._bootstrap>", line 1331, in _find_and_load_unlocked
  File "<frozen importlib._bootstrap>", line 935, in _load_unlocked
  File "<frozen importlib._bootstrap_external>", line 1027, in exec_module
  File "<frozen importlib._bootstrap>", line 488, in _call_with_frames_removed
  File "/app/crm/urls.py", line 42, in <module>
    path("companies/", include("companies.urls")),
                       ~~~~~~~^^^^^^^^^^^^^^^^^^
  File "/app/.venv/lib/python3.13/site-packages/django/urls/conf.py", line 39, in include
    urlconf_module = import_module(urlconf_module)
  File "/usr/local/lib/python3.13/importlib/__init__.py", line 88, in import_module
    return _bootstrap._gcd_import(name[level:], package, level)
           ~~~~~~~~~~~~~~~~~~~~~~^^^^^^^^^^^^^^^^^^^^^^^^^^^^^^
  File "<frozen importlib._bootstrap>", line 1387, in _gcd_import
  File "<frozen importlib._bootstrap>", line 1360, in _find_and_load
  File "<frozen importlib._bootstrap>", line 1331, in _find_and_load_unlocked
  File "<frozen importlib._bootstrap>", line 935, in _load_unlocked
  File "<frozen importlib._bootstrap_external>", line 1027, in exec_module
  File "<frozen importlib._bootstrap>", line 488, in _call_with_frames_removed
  File "/app/companies/urls.py", line 2, in <module>
    from . import views
  File "/app/companies/views.py", line 26, in <module>
    from users.permissions import RBACPermission, check_user_permission
ImportError: cannot import name 'check_user_permission' from 'users.permissions' (/app/users/permissions.py)

During handling of the above exception, another exception occurred:

Traceback (most recent call last):
  File "/app/.venv/lib/python3.13/site-packages/celery/utils/dispatch/signal.py", line 280, in send
    response = receiver(signal=self, sender=sender, **named)
  File "/app/.venv/lib/python3.13/site-packages/celery/fixups/django.py", line 101, in on_import_modules
    self.worker_fixup.validate_models()
    ~~~~~~~~~~~~~~~~~~~~~~~~~~~~~~~~~^^
  File "/app/.venv/lib/python3.13/site-packages/celery/fixups/django.py", line 141, in validate_models
    run_checks()
    ~~~~~~~~~~^^
  File "/app/.venv/lib/python3.13/site-packages/django/core/checks/registry.py", line 89, in run_checks
    new_errors = check(app_configs=app_configs, databases=databases)
  File "/app/.venv/lib/python3.13/site-packages/django/core/checks/urls.py", line 138, in check_custom_error_handlers
    path = getattr(resolver.urlconf_module, "handler%s" % status_code)
                   ^^^^^^^^^^^^^^^^^^^^^^^
  File "/app/.venv/lib/python3.13/site-packages/django/utils/functional.py", line 47, in __get__
    res = instance.__dict__[self.name] = self.func(instance)
                                         ~~~~~~~~~^^^^^^^^^^
  File "/app/.venv/lib/python3.13/site-packages/django/urls/resolvers.py", line 711, in urlconf_module
    return import_module(self.urlconf_name)
  File "/usr/local/lib/python3.13/importlib/__init__.py", line 88, in import_module
    return _bootstrap._gcd_import(name[level:], package, level)
           ~~~~~~~~~~~~~~~~~~~~~~^^^^^^^^^^^^^^^^^^^^^^^^^^^^^^
  File "<frozen importlib._bootstrap>", line 1387, in _gcd_import
  File "<frozen importlib._bootstrap>", line 1360, in _find_and_load
  File "<frozen importlib._bootstrap>", line 1331, in _find_and_load_unlocked
  File "<frozen importlib._bootstrap>", line 935, in _load_unlocked
  File "<frozen importlib._bootstrap_external>", line 1027, in exec_module
  File "<frozen importlib._bootstrap>", line 488, in _call_with_frames_removed
  File "/app/crm/urls.py", line 42, in <module>
    path("companies/", include("companies.urls")),
                       ~~~~~~~^^^^^^^^^^^^^^^^^^
  File "/app/.venv/lib/python3.13/site-packages/django/urls/conf.py", line 39, in include
    urlconf_module = import_module(urlconf_module)
  File "/usr/local/lib/python3.13/importlib/__init__.py", line 88, in import_module
    return _bootstrap._gcd_import(name[level:], package, level)
           ~~~~~~~~~~~~~~~~~~~~~~^^^^^^^^^^^^^^^^^^^^^^^^^^^^^^
  File "<frozen importlib._bootstrap>", line 1387, in _gcd_import
  File "<frozen importlib._bootstrap>", line 1360, in _find_and_load
  File "<frozen importlib._bootstrap>", line 1331, in _find_and_load_unlocked
  File "<frozen importlib._bootstrap>", line 935, in _load_unlocked
  File "<frozen importlib._bootstrap_external>", line 1027, in exec_module
  File "<frozen importlib._bootstrap>", line 488, in _call_with_frames_removed
  File "/app/companies/urls.py", line 2, in <module>
    from . import views
  File "/app/companies/views.py", line 26, in <module>
    from users.permissions import RBACPermission, check_user_permission
ImportError: cannot import name 'check_user_permission' from 'users.permissions' (/app/users/permissions.py)
INFO 2025-10-29 18:42:01,954 autoreload 32 140557371476928 Watching for file changes with StatReloader
INFO 2025-10-29 18:43:10,607 autoreload 32 140557371476928 /app/contacts/views.py changed, reloading.
INFO 2025-10-29 18:43:18,905 autoreload 36 139669510433728 Watching for file changes with StatReloader
INFO 2025-10-29 18:43:34,248 autoreload 36 139669510433728 /app/contacts/views.py changed, reloading.
INFO 2025-10-29 18:43:41,707 autoreload 40 140264764492736 Watching for file changes with StatReloader
INFO 2025-10-29 18:51:54,956 autoreload 40 140264764492736 /app/users/permissions.py changed, reloading.
INFO 2025-10-29 18:52:00,524 autoreload 32960 21280 Watching for file changes with StatReloader
INFO 2025-10-29 18:52:01,583 autoreload 44 140132839279552 Watching for file changes with StatReloader
INFO 2025-10-29 18:53:26,903 autoreload 21948 29528 Watching for file changes with StatReloader
INFO 2025-10-29 18:54:08,094 autoreload 23908 33200 Watching for file changes with StatReloader
INFO 2025-10-29 18:58:17,105 autoreload 75 139898105658304 Watching for file changes with StatReloader
INFO 2025-10-29 18:58:29,991 basehttp 75 139897755137728 "GET / HTTP/1.1" 302 0
INFO 2025-10-29 18:58:30,044 basehttp 75 139897755137728 "GET /accounts/login/?next=/ HTTP/1.1" 200 2817
INFO 2025-10-29 18:58:43,124 basehttp 75 139897755137728 "POST /accounts/login/ HTTP/1.1" 200 2750
INFO 2025-10-29 18:58:55,638 basehttp 75 139897755137728 "POST /accounts/login/ HTTP/1.1" 200 2758
INFO 2025-10-29 18:59:05,973 basehttp 75 139897755137728 "GET / HTTP/1.1" 302 0
INFO 2025-10-29 18:59:05,994 basehttp 75 139897755137728 "GET /accounts/login/?next=/ HTTP/1.1" 200 2560
INFO 2025-10-29 18:59:19,369 basehttp 75 139897755137728 "POST /accounts/login/ HTTP/1.1" 200 2758
INFO 2025-10-29 19:01:05,885 basehttp 75 139897755137728 "POST /accounts/login/ HTTP/1.1" 200 2758
INFO 2025-10-29 19:02:02,254 basehttp 75 139897755137728 "GET / HTTP/1.1" 302 0
INFO 2025-10-29 19:02:02,275 basehttp 75 139897755137728 "GET /accounts/login/?next=/ HTTP/1.1" 200 2560
INFO 2025-10-29 19:02:10,502 basehttp 75 139897755137728 "POST /accounts/login/ HTTP/1.1" 200 2758
INFO 2025-10-29 19:02:52,878 basehttp 75 139897755137728 "POST /accounts/login/ HTTP/1.1" 302 0
ERROR 2025-10-29 19:02:53,101 log 75 139897755137728 Internal Server Error: /
Traceback (most recent call last):
  File "/app/.venv/lib/python3.13/site-packages/django/core/handlers/exception.py", line 55, in inner
    response = get_response(request)
  File "/app/.venv/lib/python3.13/site-packages/django/core/handlers/base.py", line 220, in _get_response
    response = response.render()
  File "/app/.venv/lib/python3.13/site-packages/django/template/response.py", line 114, in render
    self.content = self.rendered_content
                   ^^^^^^^^^^^^^^^^^^^^^
  File "/app/.venv/lib/python3.13/site-packages/django/template/response.py", line 92, in rendered_content
    return template.render(context, self._request)
           ~~~~~~~~~~~~~~~^^^^^^^^^^^^^^^^^^^^^^^^
  File "/app/.venv/lib/python3.13/site-packages/django/template/backends/django.py", line 107, in render
    return self.template.render(context)
           ~~~~~~~~~~~~~~~~~~~~^^^^^^^^^
  File "/app/.venv/lib/python3.13/site-packages/django/template/base.py", line 171, in render
    return self._render(context)
           ~~~~~~~~~~~~^^^^^^^^^
  File "/app/.venv/lib/python3.13/site-packages/django/template/base.py", line 163, in _render
    return self.nodelist.render(context)
           ~~~~~~~~~~~~~~~~~~~~^^^^^^^^^
  File "/app/.venv/lib/python3.13/site-packages/django/template/base.py", line 1016, in render
    return SafeString("".join([node.render_annotated(context) for node in self]))
                               ~~~~~~~~~~~~~~~~~~~~~^^^^^^^^^
  File "/app/.venv/lib/python3.13/site-packages/django/template/base.py", line 977, in render_annotated
    return self.render(context)
           ~~~~~~~~~~~^^^^^^^^^
  File "/app/.venv/lib/python3.13/site-packages/django/template/loader_tags.py", line 159, in render
    return compiled_parent._render(context)
           ~~~~~~~~~~~~~~~~~~~~~~~^^^^^^^^^
  File "/app/.venv/lib/python3.13/site-packages/django/template/base.py", line 163, in _render
    return self.nodelist.render(context)
           ~~~~~~~~~~~~~~~~~~~~^^^^^^^^^
  File "/app/.venv/lib/python3.13/site-packages/django/template/base.py", line 1016, in render
    return SafeString("".join([node.render_annotated(context) for node in self]))
                               ~~~~~~~~~~~~~~~~~~~~~^^^^^^^^^
  File "/app/.venv/lib/python3.13/site-packages/django/template/base.py", line 977, in render_annotated
    return self.render(context)
           ~~~~~~~~~~~^^^^^^^^^
  File "/app/.venv/lib/python3.13/site-packages/django/template/defaulttags.py", line 327, in render
    return nodelist.render(context)
           ~~~~~~~~~~~~~~~^^^^^^^^^
  File "/app/.venv/lib/python3.13/site-packages/django/template/base.py", line 1016, in render
    return SafeString("".join([node.render_annotated(context) for node in self]))
                               ~~~~~~~~~~~~~~~~~~~~~^^^^^^^^^
  File "/app/.venv/lib/python3.13/site-packages/django/template/base.py", line 977, in render_annotated
    return self.render(context)
           ~~~~~~~~~~~^^^^^^^^^
  File "/app/.venv/lib/python3.13/site-packages/django/template/defaulttags.py", line 480, in render
    url = reverse(view_name, args=args, kwargs=kwargs, current_app=current_app)
  File "/app/.venv/lib/python3.13/site-packages/django/urls/base.py", line 98, in reverse
    resolved_url = resolver._reverse_with_prefix(view, prefix, *args, **kwargs)
  File "/app/.venv/lib/python3.13/site-packages/django/urls/resolvers.py", line 831, in _reverse_with_prefix
    raise NoReverseMatch(msg)
django.urls.exceptions.NoReverseMatch: Reverse for 'settings' not found. 'settings' is not a valid view function or pattern name.
ERROR 2025-10-29 19:02:53,106 basehttp 75 139897755137728 "GET / HTTP/1.1" 500 161549
INFO 2025-10-29 19:06:06,515 autoreload 75 139898105658304 /app/users/views.py changed, reloading.
INFO 2025-10-29 19:06:08,216 autoreload 93 140603090922432 Watching for file changes with StatReloader
INFO 2025-10-29 19:06:14,041 autoreload 93 140603090922432 /app/users/urls.py changed, reloading.
INFO 2025-10-29 19:06:15,060 autoreload 97 140590618528704 Watching for file changes with StatReloader
INFO 2025-10-29 19:08:12,172 basehttp 97 140590410888896 "GET / HTTP/1.1" 200 23935
WARNING 2025-10-29 19:08:12,683 log 97 140590318614208 Not Found: /ws/notifications/
WARNING 2025-10-29 19:08:12,683 basehttp 97 140590318614208 "GET /ws/notifications/ HTTP/1.1" 404 7177
WARNING 2025-10-29 19:08:12,783 log 97 140590402496192 Not Found: /api/dashboard/recent-activity/
WARNING 2025-10-29 19:08:12,785 basehttp 97 140590402496192 "GET /api/dashboard/recent-activity/ HTTP/1.1" 404 7312
INFO 2025-10-29 19:08:12,800 basehttp 97 140590410888896 "GET /api/dashboard/stats/ HTTP/1.1" 200 162
INFO 2025-10-29 19:08:12,803 basehttp 97 140590318614208 "GET /api/system/health/ HTTP/1.1" 200 48
INFO 2025-10-29 19:08:17,808 basehttp 97 140590318614208 "GET / HTTP/1.1" 200 23529
WARNING 2025-10-29 19:08:17,934 log 97 140590310221504 Not Found: /ws/notifications/
WARNING 2025-10-29 19:08:17,934 basehttp 97 140590310221504 "GET /ws/notifications/ HTTP/1.1" 404 7177
WARNING 2025-10-29 19:08:18,017 log 97 140590410888896 Not Found: /api/dashboard/recent-activity/
WARNING 2025-10-29 19:08:18,020 basehttp 97 140590410888896 "GET /api/dashboard/recent-activity/ HTTP/1.1" 404 7312
INFO 2025-10-29 19:08:18,038 basehttp 97 140590318614208 "GET /api/dashboard/stats/ HTTP/1.1" 200 162
INFO 2025-10-29 19:08:18,039 basehttp 97 140590402496192 "GET /api/system/health/ HTTP/1.1" 200 48
INFO 2025-10-29 19:08:23,035 basehttp 97 140590318614208 "GET / HTTP/1.1" 200 23529
WARNING 2025-10-29 19:08:23,159 log 97 140590310221504 Not Found: /ws/notifications/
WARNING 2025-10-29 19:08:23,160 basehttp 97 140590310221504 "GET /ws/notifications/ HTTP/1.1" 404 7177
WARNING 2025-10-29 19:08:23,223 log 97 140590402496192 Not Found: /api/dashboard/recent-activity/
WARNING 2025-10-29 19:08:23,226 basehttp 97 140590402496192 "GET /api/dashboard/recent-activity/ HTTP/1.1" 404 7312
INFO 2025-10-29 19:08:23,241 basehttp 97 140590318614208 "GET /api/dashboard/stats/ HTTP/1.1" 200 162
INFO 2025-10-29 19:08:23,242 basehttp 97 140590410888896 "GET /api/system/health/ HTTP/1.1" 200 48
INFO 2025-10-29 19:08:28,274 basehttp 97 140590410888896 "GET / HTTP/1.1" 200 23529
WARNING 2025-10-29 19:08:28,437 log 97 140590310221504 Not Found: /ws/notifications/
WARNING 2025-10-29 19:08:28,438 basehttp 97 140590310221504 "GET /ws/notifications/ HTTP/1.1" 404 7177
WARNING 2025-10-29 19:08:28,537 log 97 140590318614208 Not Found: /api/dashboard/recent-activity/
WARNING 2025-10-29 19:08:28,538 basehttp 97 140590318614208 "GET /api/dashboard/recent-activity/ HTTP/1.1" 404 7312
INFO 2025-10-29 19:08:28,556 basehttp 97 140590402496192 "GET /api/system/health/ HTTP/1.1" 200 48
INFO 2025-10-29 19:08:28,563 basehttp 97 140590410888896 "GET /api/dashboard/stats/ HTTP/1.1" 200 162
INFO 2025-10-29 19:08:33,622 basehttp 97 140590410888896 "GET / HTTP/1.1" 200 23529
WARNING 2025-10-29 19:08:33,904 log 97 140590310221504 Not Found: /ws/notifications/
WARNING 2025-10-29 19:08:33,908 basehttp 97 140590310221504 "GET /ws/notifications/ HTTP/1.1" 404 7177
WARNING 2025-10-29 19:08:34,011 log 97 140590402496192 Not Found: /api/dashboard/recent-activity/
WARNING 2025-10-29 19:08:34,043 basehttp 97 140590402496192 "GET /api/dashboard/recent-activity/ HTTP/1.1" 404 7312
INFO 2025-10-29 19:08:34,047 basehttp 97 140590318614208 "GET /api/system/health/ HTTP/1.1" 200 48
INFO 2025-10-29 19:08:34,056 basehttp 97 140590410888896 "GET /api/dashboard/stats/ HTTP/1.1" 200 162
INFO 2025-10-29 19:08:39,118 basehttp 97 140590410888896 "GET / HTTP/1.1" 200 23529
INFO 2025-10-29 19:08:39,260 basehttp 97 140590402496192 "GET /emails/ HTTP/1.1" 200 24007
WARNING 2025-10-29 19:08:39,632 log 97 140590410888896 Not Found: /ws/notifications/
WARNING 2025-10-29 19:08:39,640 basehttp 97 140590410888896 "GET /ws/notifications/ HTTP/1.1" 404 7177
WARNING 2025-10-29 19:08:39,913 log 97 140590410888896 Not Found: /ws/emails/
WARNING 2025-10-29 19:08:39,920 basehttp 97 140590410888896 "GET /ws/emails/ HTTP/1.1" 404 7156
INFO 2025-10-29 19:08:42,850 basehttp 97 140590402496192 "GET /dashboard/ HTTP/1.1" 200 23529
WARNING 2025-10-29 19:08:43,239 log 97 140590410888896 Not Found: /ws/notifications/
WARNING 2025-10-29 19:08:43,253 basehttp 97 140590410888896 "GET /ws/notifications/ HTTP/1.1" 404 7177
WARNING 2025-10-29 19:08:43,387 log 97 140590318614208 Not Found: /api/dashboard/recent-activity/
INFO 2025-10-29 19:08:43,412 basehttp 97 140590410888896 "GET /api/system/health/ HTTP/1.1" 200 48
WARNING 2025-10-29 19:08:43,454 basehttp 97 140590318614208 "GET /api/dashboard/recent-activity/ HTTP/1.1" 404 7312
INFO 2025-10-29 19:08:43,654 basehttp 97 140590402496192 "GET /api/dashboard/stats/ HTTP/1.1" 200 162
INFO 2025-10-29 19:08:45,907 basehttp 97 140590402496192 "GET /emails/credentials/ HTTP/1.1" 200 24032
WARNING 2025-10-29 19:08:46,243 log 97 140590310221504 Not Found: /ws/notifications/
WARNING 2025-10-29 19:08:46,251 basehttp 97 140590310221504 "GET /ws/notifications/ HTTP/1.1" 404 7177
INFO 2025-10-29 19:08:51,450 basehttp 97 140590402496192 "GET /emails/credentials/ HTTP/1.1" 200 24032
WARNING 2025-10-29 19:08:51,769 log 97 140590310221504 Not Found: /ws/notifications/
WARNING 2025-10-29 19:08:51,783 basehttp 97 140590310221504 "GET /ws/notifications/ HTTP/1.1" 404 7177
INFO 2025-10-29 19:08:53,331 basehttp 97 140590402496192 "GET /dashboard/ HTTP/1.1" 200 23529
WARNING 2025-10-29 19:08:53,493 log 97 140590310221504 Not Found: /ws/notifications/
WARNING 2025-10-29 19:08:53,494 basehttp 97 140590310221504 "GET /ws/notifications/ HTTP/1.1" 404 7177
WARNING 2025-10-29 19:08:53,547 log 97 140590318614208 Not Found: /api/dashboard/recent-activity/
WARNING 2025-10-29 19:08:53,548 basehttp 97 140590318614208 "GET /api/dashboard/recent-activity/ HTTP/1.1" 404 7312
INFO 2025-10-29 19:08:53,563 basehttp 97 140590410888896 "GET /api/system/health/ HTTP/1.1" 200 48
INFO 2025-10-29 19:08:53,568 basehttp 97 140590402496192 "GET /api/dashboard/stats/ HTTP/1.1" 200 162
INFO 2025-10-29 19:08:58,598 basehttp 97 140590402496192 "GET /dashboard/ HTTP/1.1" 200 23529
WARNING 2025-10-29 19:08:58,757 log 97 140590310221504 Not Found: /ws/notifications/
WARNING 2025-10-29 19:08:58,758 basehttp 97 140590310221504 "GET /ws/notifications/ HTTP/1.1" 404 7177
WARNING 2025-10-29 19:08:58,780 log 97 140590410888896 Not Found: /api/dashboard/recent-activity/
WARNING 2025-10-29 19:08:58,782 basehttp 97 140590410888896 "GET /api/dashboard/recent-activity/ HTTP/1.1" 404 7312
INFO 2025-10-29 19:08:58,798 basehttp 97 140590318614208 "GET /api/system/health/ HTTP/1.1" 200 48
INFO 2025-10-29 19:08:58,798 basehttp 97 140590402496192 "GET /api/dashboard/stats/ HTTP/1.1" 200 162
INFO 2025-10-29 19:09:03,825 basehttp 97 140590402496192 "GET /dashboard/ HTTP/1.1" 200 23529
WARNING 2025-10-29 19:09:03,994 log 97 140590310221504 Not Found: /ws/notifications/
WARNING 2025-10-29 19:09:03,995 basehttp 97 140590310221504 "GET /ws/notifications/ HTTP/1.1" 404 7177
WARNING 2025-10-29 19:09:04,006 log 97 140590318614208 Not Found: /api/dashboard/recent-activity/
WARNING 2025-10-29 19:09:04,007 basehttp 97 140590318614208 "GET /api/dashboard/recent-activity/ HTTP/1.1" 404 7312
INFO 2025-10-29 19:09:04,024 basehttp 97 140590402496192 "GET /api/dashboard/stats/ HTTP/1.1" 200 162
INFO 2025-10-29 19:09:04,024 basehttp 97 140590410888896 "GET /api/system/health/ HTTP/1.1" 200 48
INFO 2025-10-29 19:09:09,055 basehttp 97 140590410888896 "GET /dashboard/ HTTP/1.1" 200 23529
WARNING 2025-10-29 19:09:09,219 log 97 140590402496192 Not Found: /api/dashboard/recent-activity/
WARNING 2025-10-29 19:09:09,220 basehttp 97 140590402496192 "GET /api/dashboard/recent-activity/ HTTP/1.1" 404 7312
WARNING 2025-10-29 19:09:09,232 log 97 140590310221504 Not Found: /ws/notifications/
WARNING 2025-10-29 19:09:09,236 basehttp 97 140590310221504 "GET /ws/notifications/ HTTP/1.1" 404 7177
INFO 2025-10-29 19:09:09,239 basehttp 97 140590318614208 "GET /api/system/health/ HTTP/1.1" 200 48
INFO 2025-10-29 19:09:09,245 basehttp 97 140590410888896 "GET /api/dashboard/stats/ HTTP/1.1" 200 162
INFO 2025-10-29 19:09:14,297 basehttp 97 140590410888896 "GET /dashboard/ HTTP/1.1" 200 23529
WARNING 2025-10-29 19:09:14,486 log 97 140590318614208 Not Found: /api/dashboard/recent-activity/
WARNING 2025-10-29 19:09:14,488 basehttp 97 140590318614208 "GET /api/dashboard/recent-activity/ HTTP/1.1" 404 7312
INFO 2025-10-29 19:09:14,497 basehttp 97 140590402496192 "GET /api/system/health/ HTTP/1.1" 200 48
INFO 2025-10-29 19:09:14,508 basehttp 97 140590410888896 "GET /api/dashboard/stats/ HTTP/1.1" 200 162
WARNING 2025-10-29 19:09:14,517 log 97 140590310221504 Not Found: /ws/notifications/
WARNING 2025-10-29 19:09:14,518 basehttp 97 140590310221504 "GET /ws/notifications/ HTTP/1.1" 404 7177
INFO 2025-10-29 19:09:18,672 basehttp 97 140590410888896 "GET /emails/credentials/ HTTP/1.1" 200 24032
WARNING 2025-10-29 19:09:19,079 log 97 140590310221504 Not Found: /ws/notifications/
WARNING 2025-10-29 19:09:19,080 basehttp 97 140590310221504 "GET /ws/notifications/ HTTP/1.1" 404 7177
INFO 2025-10-29 19:09:23,004 basehttp 97 140590410888896 "GET /dashboard/ HTTP/1.1" 200 23529
WARNING 2025-10-29 19:09:23,173 log 97 140590402496192 Not Found: /api/dashboard/recent-activity/
WARNING 2025-10-29 19:09:23,176 basehttp 97 140590402496192 "GET /api/dashboard/recent-activity/ HTTP/1.1" 404 7312
INFO 2025-10-29 19:09:23,193 basehttp 97 140590410888896 "GET /api/dashboard/stats/ HTTP/1.1" 200 162
INFO 2025-10-29 19:09:23,195 basehttp 97 140590318614208 "GET /api/system/health/ HTTP/1.1" 200 48
WARNING 2025-10-29 19:09:23,605 log 97 140590310221504 Not Found: /ws/notifications/
WARNING 2025-10-29 19:09:23,606 basehttp 97 140590310221504 "GET /ws/notifications/ HTTP/1.1" 404 7177
INFO 2025-10-29 19:09:24,701 basehttp 97 140590318614208 "GET /dashboard/ HTTP/1.1" 200 23529
WARNING 2025-10-29 19:09:24,854 log 97 140590410888896 Not Found: /api/dashboard/recent-activity/
WARNING 2025-10-29 19:09:24,855 basehttp 97 140590410888896 "GET /api/dashboard/recent-activity/ HTTP/1.1" 404 7312
INFO 2025-10-29 19:09:24,865 basehttp 97 140590402496192 "GET /api/system/health/ HTTP/1.1" 200 48
INFO 2025-10-29 19:09:24,870 basehttp 97 140590318614208 "GET /api/dashboard/stats/ HTTP/1.1" 200 162
WARNING 2025-10-29 19:09:26,253 log 97 140590310221504 Not Found: /ws/notifications/
WARNING 2025-10-29 19:09:26,254 basehttp 97 140590310221504 "GET /ws/notifications/ HTTP/1.1" 404 7177
INFO 2025-10-29 19:09:31,290 basehttp 97 140590318614208 "GET /dashboard/ HTTP/1.1" 200 23529
WARNING 2025-10-29 19:09:31,459 log 97 140590402496192 Not Found: /api/dashboard/recent-activity/
WARNING 2025-10-29 19:09:31,460 basehttp 97 140590402496192 "GET /api/dashboard/recent-activity/ HTTP/1.1" 404 7312
INFO 2025-10-29 19:09:31,475 basehttp 97 140590410888896 "GET /api/system/health/ HTTP/1.1" 200 48
INFO 2025-10-29 19:09:31,477 basehttp 97 140590318614208 "GET /api/dashboard/stats/ HTTP/1.1" 200 162
ERROR 2025-10-29 19:09:32,988 log 97 140590318614208 Internal Server Error: /companies/
Traceback (most recent call last):
  File "/app/.venv/lib/python3.13/site-packages/django/core/handlers/exception.py", line 55, in inner
    response = get_response(request)
  File "/app/.venv/lib/python3.13/site-packages/django/core/handlers/base.py", line 220, in _get_response
    response = response.render()
  File "/app/.venv/lib/python3.13/site-packages/django/template/response.py", line 114, in render
    self.content = self.rendered_content
                   ^^^^^^^^^^^^^^^^^^^^^
  File "/app/.venv/lib/python3.13/site-packages/django/template/response.py", line 90, in rendered_content
    template = self.resolve_template(self.template_name)
  File "/app/.venv/lib/python3.13/site-packages/django/template/response.py", line 72, in resolve_template
    return select_template(template, using=self.using)
  File "/app/.venv/lib/python3.13/site-packages/django/template/loader.py", line 47, in select_template
    raise TemplateDoesNotExist(", ".join(template_name_list), chain=chain)
django.template.exceptions.TemplateDoesNotExist: companies/company_list.html, companies/company_list.html
ERROR 2025-10-29 19:09:32,991 basehttp 97 140590318614208 "GET /companies/ HTTP/1.1" 500 89319
